<sdf version='1.6'>
  <world name='default'>
    <model name='ground_plane'>
      <static>1</static>
      <link name='link'>
        <collision name='collision'>
          <geometry>
            <plane>
              <normal>0 0 1</normal>
              <size>100 100</size>
            </plane>
          </geometry>
          <surface>
            <friction>
              <ode>
                <mu>100</mu>
                <mu2>50</mu2>
              </ode>
              <torsional>
                <ode/>
              </torsional>
            </friction>
            <contact>
              <ode/>
            </contact>
            <bounce/>
          </surface>
          <max_contacts>10</max_contacts>
        </collision>
        <visual name='visual'>
          <cast_shadows>0</cast_shadows>
          <geometry>
            <plane>
              <normal>0 0 1</normal>
              <size>100 100</size>
            </plane>
          </geometry>
          <material>
            <script>
              <uri>file://media/materials/scripts/gazebo.material</uri>
              <name>Gazebo/Grey</name>
            </script>
          </material>
        </visual>
        <self_collide>0</self_collide>
        <kinematic>0</kinematic>
        <gravity>1</gravity>
      </link>
    </model>
    <light name='sun' type='directional'>
      <cast_shadows>1</cast_shadows>
      <pose frame=''>0 0 10 0 -0 0</pose>
      <diffuse>0.8 0.8 0.8 1</diffuse>
      <specular>0.1 0.1 0.1 1</specular>
      <attenuation>
        <range>1000</range>
        <constant>0.9</constant>
        <linear>0.01</linear>
        <quadratic>0.001</quadratic>
      </attenuation>
      <direction>-0.5 0.5 -1</direction>
    </light>
    <gui fullscreen='0'>
      <camera name='user_camera'>
        <pose frame=''>-2.73827 3.31716 1.9107 0 0.307643 -0.450993</pose>
        <view_controller>orbit</view_controller>
        <projection_type>perspective</projection_type>
      </camera>
    </gui>
    <gravity>0 0 -9.8</gravity>
    <magnetic_field>6e-06 2.3e-05 -4.2e-05</magnetic_field>
    <atmosphere type='adiabatic'/>
    <physics name='default_physics' default='0' type='ode'>
      <max_step_size>0.001</max_step_size>
      <real_time_factor>1</real_time_factor>
      <real_time_update_rate>1000</real_time_update_rate>
    </physics>
    <scene>
      <ambient>0.4 0.4 0.4 1</ambient>
      <background>0.7 0.7 0.7 1</background>
      <shadows>1</shadows>
    </scene>
    <spherical_coordinates>
      <surface_model>EARTH_WGS84</surface_model>
      <latitude_deg>0</latitude_deg>
      <longitude_deg>0</longitude_deg>
      <elevation>0</elevation>
      <heading_deg>0</heading_deg>
    </spherical_coordinates>
    <model name='adabot'>
      <link name='base_link'>
        <pose frame=''>0 0 0 0 -0 0</pose>
        <inertial>
          <pose frame=''>0 0 0 0 -0 0</pose>
          <mass>0.1225</mass>
          <inertia>
            <ixx>6.2526e-05</ixx>
            <ixy>0</ixy>
            <ixz>0</ixz>
            <iyy>0.000114589</iyy>
            <iyz>0</iyz>
            <izz>0.000152104</izz>
          </inertia>
        </inertial>
        <collision name='base_link_collision'>
          <pose frame=''>0 0 0.011 0 -0 0</pose>
          <geometry>
            <box>
              <size>0.1 0.07 0.035</size>
            </box>
          </geometry>
          <max_contacts>10</max_contacts>
          <surface>
            <contact>
              <ode/>
            </contact>
            <bounce/>
            <friction>
              <torsional>
                <ode/>
              </torsional>
              <ode/>
            </friction>
          </surface>
        </collision>
        <visual name='base_link_visual'>
          <pose frame=''>0 0 0.011 0 -0 0</pose>
          <geometry>
            <box>
              <size>0.1 0.07 0.035</size>
            </box>
          </geometry>
        </visual>
        <self_collide>0</self_collide>
        <kinematic>0</kinematic>
        <gravity>1</gravity>
      </link>
      <link name='wh-back-left'>
        <pose frame=''>-0.05 -0.0375 0.011 0 -0 0</pose>
        <inertial>
          <pose frame=''>0 0 0 0 -0 0</pose>
          <mass>0.00314593</mass>
          <inertia>
            <ixx>3.21147e-07</ixx>
            <ixy>0</ixy>
            <ixz>0</ixz>
            <iyy>3.21147e-07</iyy>
            <iyz>0</iyz>
            <izz>6.29185e-07</izz>
          </inertia>
        </inertial>
        <collision name='wh-back-left_collision'>
          <pose frame=''>0 0 0 1.57075 -0 0</pose>
          <geometry>
            <cylinder>
              <length>0.005</length>
              <radius>0.02</radius>
            </cylinder>
          </geometry>
          <max_contacts>10</max_contacts>
          <surface>
            <contact>
              <ode/>
            </contact>
            <bounce/>
            <friction>
              <torsional>
                <ode/>
              </torsional>
              <ode/>
            </friction>
          </surface>
        </collision>
        <visual name='wh-back-left_visual'>
          <pose frame=''>0 0 0 1.57075 -0 0</pose>
          <geometry>
            <cylinder>
              <length>0.005</length>
              <radius>0.02</radius>
            </cylinder>
          </geometry>
        </visual>
        <self_collide>0</self_collide>
        <kinematic>0</kinematic>
        <gravity>1</gravity>
      </link>
      <joint name='ax-back-left' type='revolute'>
        <child>wh-back-left</child>
        <parent>base_link</parent>
        <axis>
          <xyz>0 1 0</xyz>
          <limit>
            <lower>-1e+16</lower>
            <upper>1e+16</upper>
          </limit>
          <dynamics>
            <spring_reference>0</spring_reference>
            <spring_stiffness>0</spring_stiffness>
          </dynamics>
          <use_parent_model_frame>1</use_parent_model_frame>
        </axis>
      </joint>
      <link name='wg-back-left-1'>
        <pose frame=''>-0.05 -0.0375 0.011 0 1.25664 0</pose>
        <inertial>
          <pose frame=''>0 0 0 0 -0 0</pose>
          <mass>4e-05</mass>
          <inertia>
            <ixx>1.66667e-11</ixx>
            <ixy>0</ixy>
            <ixz>0</ixz>
            <iyy>5.34667e-09</iyy>
            <iyz>0</iyz>
            <izz>5.33667e-09</izz>
          </inertia>
        </inertial>
        <collision name='wg-back-left-1_collision'>
          <pose frame=''>0 0 0 0 -0 0</pose>
          <geometry>
            <box>
              <size>0.04 0.001 0.002</size>
            </box>
          </geometry>
          <max_contacts>10</max_contacts>
          <surface>
            <contact>
              <ode/>
            </contact>
            <bounce/>
            <friction>
              <torsional>
                <ode/>
              </torsional>
              <ode/>
            </friction>
          </surface>
        </collision>
        <visual name='wg-back-left-1_visual'>
          <pose frame=''>0 0 0 0 -0 0</pose>
          <geometry>
            <box>
              <size>0.04 0.001 0.002</size>
            </box>
          </geometry>
        </visual>
        <self_collide>0</self_collide>
        <kinematic>0</kinematic>
        <gravity>1</gravity>
      </link>
      <joint name='wg-back-left-1-joint' type='prismatic'>
        <child>wg-back-left-1</child>
        <parent>wh-back-left</parent>
        <axis>
          <xyz>0.309017 0 -0.951057</xyz>
          <limit>
            <lower>0</lower>
            <upper>0.008</upper>
            <effort>1</effort>
            <velocity>1</velocity>
          </limit>
          <dynamics>
            <spring_reference>0</spring_reference>
            <spring_stiffness>0</spring_stiffness>
          </dynamics>
          <use_parent_model_frame>1</use_parent_model_frame>
        </axis>
      </joint>
      <link name='wg-back-left-2'>
        <pose frame=''>-0.05 -0.0375 0.011 3.14159 0.628319 3.14159</pose>
        <inertial>
          <pose frame=''>0 0 0 0 -0 0</pose>
          <mass>4e-05</mass>
          <inertia>
            <ixx>1.66667e-11</ixx>
            <ixy>0</ixy>
            <ixz>0</ixz>
            <iyy>5.34667e-09</iyy>
            <iyz>0</iyz>
            <izz>5.33667e-09</izz>
          </inertia>
        </inertial>
        <collision name='wg-back-left-2_collision'>
          <pose frame=''>0 0 0 0 -0 0</pose>
          <geometry>
            <box>
              <size>0.04 0.001 0.002</size>
            </box>
          </geometry>
          <max_contacts>10</max_contacts>
          <surface>
            <contact>
              <ode/>
            </contact>
            <bounce/>
            <friction>
              <torsional>
                <ode/>
              </torsional>
              <ode/>
            </friction>
          </surface>
        </collision>
        <visual name='wg-back-left-2_visual'>
          <pose frame=''>0 0 0 0 -0 0</pose>
          <geometry>
            <box>
              <size>0.04 0.001 0.002</size>
            </box>
          </geometry>
        </visual>
        <self_collide>0</self_collide>
        <kinematic>0</kinematic>
        <gravity>1</gravity>
      </link>
      <joint name='wg-back-left-2-joint' type='prismatic'>
        <child>wg-back-left-2</child>
        <parent>wh-back-left</parent>
        <axis>
          <xyz>-0.809017 0 -0.587785</xyz>
          <limit>
            <lower>0</lower>
            <upper>0.008</upper>
            <effort>1</effort>
            <velocity>1</velocity>
          </limit>
          <dynamics>
            <spring_reference>0</spring_reference>
            <spring_stiffness>0</spring_stiffness>
          </dynamics>
          <use_parent_model_frame>1</use_parent_model_frame>
        </axis>
      </joint>
      <link name='wg-back-left-3'>
        <pose frame=''>-0.05 -0.0375 0.011 3.14159 -0.628319 -3.14159</pose>
        <inertial>
          <pose frame=''>0 0 0 0 -0 0</pose>
          <mass>4e-05</mass>
          <inertia>
            <ixx>1.66667e-11</ixx>
            <ixy>0</ixy>
            <ixz>0</ixz>
            <iyy>5.34667e-09</iyy>
            <iyz>0</iyz>
            <izz>5.33667e-09</izz>
          </inertia>
        </inertial>
        <collision name='wg-back-left-3_collision'>
          <pose frame=''>0 0 0 0 -0 0</pose>
          <geometry>
            <box>
              <size>0.04 0.001 0.002</size>
            </box>
          </geometry>
          <max_contacts>10</max_contacts>
          <surface>
            <contact>
              <ode/>
            </contact>
            <bounce/>
            <friction>
              <torsional>
                <ode/>
              </torsional>
              <ode/>
            </friction>
          </surface>
        </collision>
        <visual name='wg-back-left-3_visual'>
          <pose frame=''>0 0 0 0 -0 0</pose>
          <geometry>
            <box>
              <size>0.04 0.001 0.002</size>
            </box>
          </geometry>
        </visual>
        <self_collide>0</self_collide>
        <kinematic>0</kinematic>
        <gravity>1</gravity>
      </link>
      <joint name='wg-back-left-3-joint' type='prismatic'>
        <child>wg-back-left-3</child>
        <parent>wh-back-left</parent>
        <axis>
          <xyz>-0.809017 0 0.587785</xyz>
          <limit>
            <lower>0</lower>
            <upper>0.008</upper>
            <effort>1</effort>
            <velocity>1</velocity>
          </limit>
          <dynamics>
            <spring_reference>0</spring_reference>
            <spring_stiffness>0</spring_stiffness>
          </dynamics>
          <use_parent_model_frame>1</use_parent_model_frame>
        </axis>
      </joint>
      <link name='wg-back-left-4'>
        <pose frame=''>-0.05 -0.0375 0.011 0 -1.25664 0</pose>
        <inertial>
          <pose frame=''>0 0 0 0 -0 0</pose>
          <mass>4e-05</mass>
          <inertia>
            <ixx>1.66667e-11</ixx>
            <ixy>0</ixy>
            <ixz>0</ixz>
            <iyy>5.34667e-09</iyy>
            <iyz>0</iyz>
            <izz>5.33667e-09</izz>
          </inertia>
        </inertial>
        <collision name='wg-back-left-4_collision'>
          <pose frame=''>0 0 0 0 -0 0</pose>
          <geometry>
            <box>
              <size>0.04 0.001 0.002</size>
            </box>
          </geometry>
          <max_contacts>10</max_contacts>
          <surface>
            <contact>
              <ode/>
            </contact>
            <bounce/>
            <friction>
              <torsional>
                <ode/>
              </torsional>
              <ode/>
            </friction>
          </surface>
        </collision>
        <visual name='wg-back-left-4_visual'>
          <pose frame=''>0 0 0 0 -0 0</pose>
          <geometry>
            <box>
              <size>0.04 0.001 0.002</size>
            </box>
          </geometry>
        </visual>
        <self_collide>0</self_collide>
        <kinematic>0</kinematic>
        <gravity>1</gravity>
      </link>
      <joint name='wg-back-left-4-joint' type='prismatic'>
        <child>wg-back-left-4</child>
        <parent>wh-back-left</parent>
        <axis>
          <xyz>0.309017 0 0.951057</xyz>
          <limit>
            <lower>0</lower>
            <upper>0.008</upper>
            <effort>1</effort>
            <velocity>1</velocity>
          </limit>
          <dynamics>
            <spring_reference>0</spring_reference>
            <spring_stiffness>0</spring_stiffness>
          </dynamics>
          <use_parent_model_frame>1</use_parent_model_frame>
        </axis>
      </joint>
      <link name='wg-back-left-5'>
        <pose frame=''>-0.05 -0.0375 0.011 0 -0 0</pose>
        <inertial>
          <pose frame=''>0 0 0 0 -0 0</pose>
          <mass>4e-05</mass>
          <inertia>
            <ixx>1.66667e-11</ixx>
            <ixy>0</ixy>
            <ixz>0</ixz>
            <iyy>5.34667e-09</iyy>
            <iyz>0</iyz>
            <izz>5.33667e-09</izz>
          </inertia>
        </inertial>
        <collision name='wg-back-left-5_collision'>
          <pose frame=''>0 0 0 0 -0 0</pose>
          <geometry>
            <box>
              <size>0.04 0.001 0.002</size>
            </box>
          </geometry>
          <max_contacts>10</max_contacts>
          <surface>
            <contact>
              <ode/>
            </contact>
            <bounce/>
            <friction>
              <torsional>
                <ode/>
              </torsional>
              <ode/>
            </friction>
          </surface>
        </collision>
        <visual name='wg-back-left-5_visual'>
          <pose frame=''>0 0 0 0 -0 0</pose>
          <geometry>
            <box>
              <size>0.04 0.001 0.002</size>
            </box>
          </geometry>
        </visual>
        <self_collide>0</self_collide>
        <kinematic>0</kinematic>
        <gravity>1</gravity>
      </link>
      <joint name='wg-back-left-5-joint' type='prismatic'>
        <child>wg-back-left-5</child>
        <parent>wh-back-left</parent>
        <axis>
          <xyz>1 -0 -0</xyz>
          <limit>
            <lower>0</lower>
            <upper>0.008</upper>
            <effort>1</effort>
            <velocity>1</velocity>
          </limit>
          <dynamics>
            <spring_reference>0</spring_reference>
            <spring_stiffness>0</spring_stiffness>
          </dynamics>
          <use_parent_model_frame>1</use_parent_model_frame>
        </axis>
      </joint>
      <link name='wh-back-right'>
        <pose frame=''>-0.05 0.0375 0.011 0 -0 0</pose>
        <inertial>
          <pose frame=''>0 0 0 0 -0 0</pose>
          <mass>0.00314593</mass>
          <inertia>
            <ixx>3.21147e-07</ixx>
            <ixy>0</ixy>
            <ixz>0</ixz>
            <iyy>3.21147e-07</iyy>
            <iyz>0</iyz>
            <izz>6.29185e-07</izz>
          </inertia>
        </inertial>
        <collision name='wh-back-right_collision'>
          <pose frame=''>0 0 0 1.57075 -0 0</pose>
          <geometry>
            <cylinder>
              <length>0.005</length>
              <radius>0.02</radius>
            </cylinder>
          </geometry>
          <max_contacts>10</max_contacts>
          <surface>
            <contact>
              <ode/>
            </contact>
            <bounce/>
            <friction>
              <torsional>
                <ode/>
              </torsional>
              <ode/>
            </friction>
          </surface>
        </collision>
        <visual name='wh-back-right_visual'>
          <pose frame=''>0 0 0 1.57075 -0 0</pose>
          <geometry>
            <cylinder>
              <length>0.005</length>
              <radius>0.02</radius>
            </cylinder>
          </geometry>
        </visual>
        <self_collide>0</self_collide>
        <kinematic>0</kinematic>
        <gravity>1</gravity>
      </link>
      <joint name='ax-back-right' type='revolute'>
        <child>wh-back-right</child>
        <parent>base_link</parent>
        <axis>
          <xyz>0 1 0</xyz>
          <limit>
            <lower>-1e+16</lower>
            <upper>1e+16</upper>
          </limit>
          <dynamics>
            <spring_reference>0</spring_reference>
            <spring_stiffness>0</spring_stiffness>
          </dynamics>
          <use_parent_model_frame>1</use_parent_model_frame>
        </axis>
      </joint>
      <link name='wg-back-right-1'>
        <pose frame=''>-0.05 0.0375 0.011 0 1.25664 0</pose>
        <inertial>
          <pose frame=''>0 0 0 0 -0 0</pose>
          <mass>4e-05</mass>
          <inertia>
            <ixx>1.66667e-11</ixx>
            <ixy>0</ixy>
            <ixz>0</ixz>
            <iyy>5.34667e-09</iyy>
            <iyz>0</iyz>
            <izz>5.33667e-09</izz>
          </inertia>
        </inertial>
        <collision name='wg-back-right-1_collision'>
          <pose frame=''>0 0 0 0 -0 0</pose>
          <geometry>
            <box>
              <size>0.04 0.001 0.002</size>
            </box>
          </geometry>
          <max_contacts>10</max_contacts>
          <surface>
            <contact>
              <ode/>
            </contact>
            <bounce/>
            <friction>
              <torsional>
                <ode/>
              </torsional>
              <ode/>
            </friction>
          </surface>
        </collision>
        <visual name='wg-back-right-1_visual'>
          <pose frame=''>0 0 0 0 -0 0</pose>
          <geometry>
            <box>
              <size>0.04 0.001 0.002</size>
            </box>
          </geometry>
        </visual>
        <self_collide>0</self_collide>
        <kinematic>0</kinematic>
        <gravity>1</gravity>
      </link>
      <joint name='wg-back-right-1-joint' type='prismatic'>
        <child>wg-back-right-1</child>
        <parent>wh-back-right</parent>
        <axis>
          <xyz>0.309017 0 -0.951057</xyz>
          <limit>
            <lower>0</lower>
            <upper>0.008</upper>
            <effort>1</effort>
            <velocity>1</velocity>
          </limit>
          <dynamics>
            <spring_reference>0</spring_reference>
            <spring_stiffness>0</spring_stiffness>
          </dynamics>
          <use_parent_model_frame>1</use_parent_model_frame>
        </axis>
      </joint>
      <link name='wg-back-right-2'>
        <pose frame=''>-0.05 0.0375 0.011 3.14159 0.628319 3.14159</pose>
        <inertial>
          <pose frame=''>0 0 0 0 -0 0</pose>
          <mass>4e-05</mass>
          <inertia>
            <ixx>1.66667e-11</ixx>
            <ixy>0</ixy>
            <ixz>0</ixz>
            <iyy>5.34667e-09</iyy>
            <iyz>0</iyz>
            <izz>5.33667e-09</izz>
          </inertia>
        </inertial>
        <collision name='wg-back-right-2_collision'>
          <pose frame=''>0 0 0 0 -0 0</pose>
          <geometry>
            <box>
              <size>0.04 0.001 0.002</size>
            </box>
          </geometry>
          <max_contacts>10</max_contacts>
          <surface>
            <contact>
              <ode/>
            </contact>
            <bounce/>
            <friction>
              <torsional>
                <ode/>
              </torsional>
              <ode/>
            </friction>
          </surface>
        </collision>
        <visual name='wg-back-right-2_visual'>
          <pose frame=''>0 0 0 0 -0 0</pose>
          <geometry>
            <box>
              <size>0.04 0.001 0.002</size>
            </box>
          </geometry>
        </visual>
        <self_collide>0</self_collide>
        <kinematic>0</kinematic>
        <gravity>1</gravity>
      </link>
      <joint name='wg-back-right-2-joint' type='prismatic'>
        <child>wg-back-right-2</child>
        <parent>wh-back-right</parent>
        <axis>
          <xyz>-0.809017 0 -0.587785</xyz>
          <limit>
            <lower>0</lower>
            <upper>0.008</upper>
            <effort>1</effort>
            <velocity>1</velocity>
          </limit>
          <dynamics>
            <spring_reference>0</spring_reference>
            <spring_stiffness>0</spring_stiffness>
          </dynamics>
          <use_parent_model_frame>1</use_parent_model_frame>
        </axis>
      </joint>
      <link name='wg-back-right-3'>
        <pose frame=''>-0.05 0.0375 0.011 3.14159 -0.628319 -3.14159</pose>
        <inertial>
          <pose frame=''>0 0 0 0 -0 0</pose>
          <mass>4e-05</mass>
          <inertia>
            <ixx>1.66667e-11</ixx>
            <ixy>0</ixy>
            <ixz>0</ixz>
            <iyy>5.34667e-09</iyy>
            <iyz>0</iyz>
            <izz>5.33667e-09</izz>
          </inertia>
        </inertial>
        <collision name='wg-back-right-3_collision'>
          <pose frame=''>0 0 0 0 -0 0</pose>
          <geometry>
            <box>
              <size>0.04 0.001 0.002</size>
            </box>
          </geometry>
          <max_contacts>10</max_contacts>
          <surface>
            <contact>
              <ode/>
            </contact>
            <bounce/>
            <friction>
              <torsional>
                <ode/>
              </torsional>
              <ode/>
            </friction>
          </surface>
        </collision>
        <visual name='wg-back-right-3_visual'>
          <pose frame=''>0 0 0 0 -0 0</pose>
          <geometry>
            <box>
              <size>0.04 0.001 0.002</size>
            </box>
          </geometry>
        </visual>
        <self_collide>0</self_collide>
        <kinematic>0</kinematic>
        <gravity>1</gravity>
      </link>
      <joint name='wg-back-right-3-joint' type='prismatic'>
        <child>wg-back-right-3</child>
        <parent>wh-back-right</parent>
        <axis>
          <xyz>-0.809017 0 0.587785</xyz>
          <limit>
            <lower>0</lower>
            <upper>0.008</upper>
            <effort>1</effort>
            <velocity>1</velocity>
          </limit>
          <dynamics>
            <spring_reference>0</spring_reference>
            <spring_stiffness>0</spring_stiffness>
          </dynamics>
          <use_parent_model_frame>1</use_parent_model_frame>
        </axis>
      </joint>
      <link name='wg-back-right-4'>
        <pose frame=''>-0.05 0.0375 0.011 0 -1.25664 0</pose>
        <inertial>
          <pose frame=''>0 0 0 0 -0 0</pose>
          <mass>4e-05</mass>
          <inertia>
            <ixx>1.66667e-11</ixx>
            <ixy>0</ixy>
            <ixz>0</ixz>
            <iyy>5.34667e-09</iyy>
            <iyz>0</iyz>
            <izz>5.33667e-09</izz>
          </inertia>
        </inertial>
        <collision name='wg-back-right-4_collision'>
          <pose frame=''>0 0 0 0 -0 0</pose>
          <geometry>
            <box>
              <size>0.04 0.001 0.002</size>
            </box>
          </geometry>
          <max_contacts>10</max_contacts>
          <surface>
            <contact>
              <ode/>
            </contact>
            <bounce/>
            <friction>
              <torsional>
                <ode/>
              </torsional>
              <ode/>
            </friction>
          </surface>
        </collision>
        <visual name='wg-back-right-4_visual'>
          <pose frame=''>0 0 0 0 -0 0</pose>
          <geometry>
            <box>
              <size>0.04 0.001 0.002</size>
            </box>
          </geometry>
        </visual>
        <self_collide>0</self_collide>
        <kinematic>0</kinematic>
        <gravity>1</gravity>
      </link>
      <joint name='wg-back-right-4-joint' type='prismatic'>
        <child>wg-back-right-4</child>
        <parent>wh-back-right</parent>
        <axis>
          <xyz>0.309017 0 0.951057</xyz>
          <limit>
            <lower>0</lower>
            <upper>0.008</upper>
            <effort>1</effort>
            <velocity>1</velocity>
          </limit>
          <dynamics>
            <spring_reference>0</spring_reference>
            <spring_stiffness>0</spring_stiffness>
          </dynamics>
          <use_parent_model_frame>1</use_parent_model_frame>
        </axis>
      </joint>
      <link name='wg-back-right-5'>
        <pose frame=''>-0.05 0.0375 0.011 0 -0 0</pose>
        <inertial>
          <pose frame=''>0 0 0 0 -0 0</pose>
          <mass>4e-05</mass>
          <inertia>
            <ixx>1.66667e-11</ixx>
            <ixy>0</ixy>
            <ixz>0</ixz>
            <iyy>5.34667e-09</iyy>
            <iyz>0</iyz>
            <izz>5.33667e-09</izz>
          </inertia>
        </inertial>
        <collision name='wg-back-right-5_collision'>
          <pose frame=''>0 0 0 0 -0 0</pose>
          <geometry>
            <box>
              <size>0.04 0.001 0.002</size>
            </box>
          </geometry>
          <max_contacts>10</max_contacts>
          <surface>
            <contact>
              <ode/>
            </contact>
            <bounce/>
            <friction>
              <torsional>
                <ode/>
              </torsional>
              <ode/>
            </friction>
          </surface>
        </collision>
        <visual name='wg-back-right-5_visual'>
          <pose frame=''>0 0 0 0 -0 0</pose>
          <geometry>
            <box>
              <size>0.04 0.001 0.002</size>
            </box>
          </geometry>
        </visual>
        <self_collide>0</self_collide>
        <kinematic>0</kinematic>
        <gravity>1</gravity>
      </link>
      <joint name='wg-back-right-5-joint' type='prismatic'>
        <child>wg-back-right-5</child>
        <parent>wh-back-right</parent>
        <axis>
          <xyz>1 -0 -0</xyz>
          <limit>
            <lower>0</lower>
            <upper>0.008</upper>
            <effort>1</effort>
            <velocity>1</velocity>
          </limit>
          <dynamics>
            <spring_reference>0</spring_reference>
            <spring_stiffness>0</spring_stiffness>
          </dynamics>
          <use_parent_model_frame>1</use_parent_model_frame>
        </axis>
      </joint>
      <link name='wh-front-left'>
        <pose frame=''>0.05 -0.0375 0.011 0 -0 0</pose>
        <inertial>
          <pose frame=''>0 0 0 0 -0 0</pose>
          <mass>0.00314593</mass>
          <inertia>
            <ixx>3.21147e-07</ixx>
            <ixy>0</ixy>
            <ixz>0</ixz>
            <iyy>3.21147e-07</iyy>
            <iyz>0</iyz>
            <izz>6.29185e-07</izz>
          </inertia>
        </inertial>
        <collision name='wh-front-left_collision'>
          <pose frame=''>0 0 0 1.57075 -0 0</pose>
          <geometry>
            <cylinder>
              <length>0.005</length>
              <radius>0.02</radius>
            </cylinder>
          </geometry>
          <max_contacts>10</max_contacts>
          <surface>
            <contact>
              <ode/>
            </contact>
            <bounce/>
            <friction>
              <torsional>
                <ode/>
              </torsional>
              <ode/>
            </friction>
          </surface>
        </collision>
        <visual name='wh-front-left_visual'>
          <pose frame=''>0 0 0 1.57075 -0 0</pose>
          <geometry>
            <cylinder>
              <length>0.005</length>
              <radius>0.02</radius>
            </cylinder>
          </geometry>
        </visual>
        <self_collide>0</self_collide>
        <kinematic>0</kinematic>
        <gravity>1</gravity>
      </link>
      <joint name='ax-front-left' type='revolute'>
        <child>wh-front-left</child>
        <parent>base_link</parent>
        <axis>
          <xyz>0 1 0</xyz>
          <limit>
            <lower>-1e+16</lower>
            <upper>1e+16</upper>
          </limit>
          <dynamics>
            <spring_reference>0</spring_reference>
            <spring_stiffness>0</spring_stiffness>
          </dynamics>
          <use_parent_model_frame>1</use_parent_model_frame>
        </axis>
      </joint>
      <link name='wg-front-left-1'>
        <pose frame=''>0.05 -0.0375 0.011 0 1.25664 0</pose>
        <inertial>
          <pose frame=''>0 0 0 0 -0 0</pose>
          <mass>4e-05</mass>
          <inertia>
            <ixx>1.66667e-11</ixx>
            <ixy>0</ixy>
            <ixz>0</ixz>
            <iyy>5.34667e-09</iyy>
            <iyz>0</iyz>
            <izz>5.33667e-09</izz>
          </inertia>
        </inertial>
        <collision name='wg-front-left-1_collision'>
          <pose frame=''>0 0 0 0 -0 0</pose>
          <geometry>
            <box>
              <size>0.04 0.001 0.002</size>
            </box>
          </geometry>
          <max_contacts>10</max_contacts>
          <surface>
            <contact>
              <ode/>
            </contact>
            <bounce/>
            <friction>
              <torsional>
                <ode/>
              </torsional>
              <ode/>
            </friction>
          </surface>
        </collision>
        <visual name='wg-front-left-1_visual'>
          <pose frame=''>0 0 0 0 -0 0</pose>
          <geometry>
            <box>
              <size>0.04 0.001 0.002</size>
            </box>
          </geometry>
        </visual>
        <self_collide>0</self_collide>
        <kinematic>0</kinematic>
        <gravity>1</gravity>
      </link>
      <joint name='wg-front-left-1-joint' type='prismatic'>
        <child>wg-front-left-1</child>
        <parent>wh-front-left</parent>
        <axis>
          <xyz>0.309017 0 -0.951057</xyz>
          <limit>
            <lower>0</lower>
            <upper>0.008</upper>
            <effort>1</effort>
            <velocity>1</velocity>
          </limit>
          <dynamics>
            <spring_reference>0</spring_reference>
            <spring_stiffness>0</spring_stiffness>
          </dynamics>
          <use_parent_model_frame>1</use_parent_model_frame>
        </axis>
      </joint>
      <link name='wg-front-left-2'>
        <pose frame=''>0.05 -0.0375 0.011 3.14159 0.628319 3.14159</pose>
        <inertial>
          <pose frame=''>0 0 0 0 -0 0</pose>
          <mass>4e-05</mass>
          <inertia>
            <ixx>1.66667e-11</ixx>
            <ixy>0</ixy>
            <ixz>0</ixz>
            <iyy>5.34667e-09</iyy>
            <iyz>0</iyz>
            <izz>5.33667e-09</izz>
          </inertia>
        </inertial>
        <collision name='wg-front-left-2_collision'>
          <pose frame=''>0 0 0 0 -0 0</pose>
          <geometry>
            <box>
              <size>0.04 0.001 0.002</size>
            </box>
          </geometry>
          <max_contacts>10</max_contacts>
          <surface>
            <contact>
              <ode/>
            </contact>
            <bounce/>
            <friction>
              <torsional>
                <ode/>
              </torsional>
              <ode/>
            </friction>
          </surface>
        </collision>
        <visual name='wg-front-left-2_visual'>
          <pose frame=''>0 0 0 0 -0 0</pose>
          <geometry>
            <box>
              <size>0.04 0.001 0.002</size>
            </box>
          </geometry>
        </visual>
        <self_collide>0</self_collide>
        <kinematic>0</kinematic>
        <gravity>1</gravity>
      </link>
      <joint name='wg-front-left-2-joint' type='prismatic'>
        <child>wg-front-left-2</child>
        <parent>wh-front-left</parent>
        <axis>
          <xyz>-0.809017 0 -0.587785</xyz>
          <limit>
            <lower>0</lower>
            <upper>0.008</upper>
            <effort>1</effort>
            <velocity>1</velocity>
          </limit>
          <dynamics>
            <spring_reference>0</spring_reference>
            <spring_stiffness>0</spring_stiffness>
          </dynamics>
          <use_parent_model_frame>1</use_parent_model_frame>
        </axis>
      </joint>
      <link name='wg-front-left-3'>
        <pose frame=''>0.05 -0.0375 0.011 3.14159 -0.628319 -3.14159</pose>
        <inertial>
          <pose frame=''>0 0 0 0 -0 0</pose>
          <mass>4e-05</mass>
          <inertia>
            <ixx>1.66667e-11</ixx>
            <ixy>0</ixy>
            <ixz>0</ixz>
            <iyy>5.34667e-09</iyy>
            <iyz>0</iyz>
            <izz>5.33667e-09</izz>
          </inertia>
        </inertial>
        <collision name='wg-front-left-3_collision'>
          <pose frame=''>0 0 0 0 -0 0</pose>
          <geometry>
            <box>
              <size>0.04 0.001 0.002</size>
            </box>
          </geometry>
          <max_contacts>10</max_contacts>
          <surface>
            <contact>
              <ode/>
            </contact>
            <bounce/>
            <friction>
              <torsional>
                <ode/>
              </torsional>
              <ode/>
            </friction>
          </surface>
        </collision>
        <visual name='wg-front-left-3_visual'>
          <pose frame=''>0 0 0 0 -0 0</pose>
          <geometry>
            <box>
              <size>0.04 0.001 0.002</size>
            </box>
          </geometry>
        </visual>
        <self_collide>0</self_collide>
        <kinematic>0</kinematic>
        <gravity>1</gravity>
      </link>
      <joint name='wg-front-left-3-joint' type='prismatic'>
        <child>wg-front-left-3</child>
        <parent>wh-front-left</parent>
        <axis>
          <xyz>-0.809017 0 0.587785</xyz>
          <limit>
            <lower>0</lower>
            <upper>0.008</upper>
            <effort>1</effort>
            <velocity>1</velocity>
          </limit>
          <dynamics>
            <spring_reference>0</spring_reference>
            <spring_stiffness>0</spring_stiffness>
          </dynamics>
          <use_parent_model_frame>1</use_parent_model_frame>
        </axis>
      </joint>
      <link name='wg-front-left-4'>
        <pose frame=''>0.05 -0.0375 0.011 0 -1.25664 0</pose>
        <inertial>
          <pose frame=''>0 0 0 0 -0 0</pose>
          <mass>4e-05</mass>
          <inertia>
            <ixx>1.66667e-11</ixx>
            <ixy>0</ixy>
            <ixz>0</ixz>
            <iyy>5.34667e-09</iyy>
            <iyz>0</iyz>
            <izz>5.33667e-09</izz>
          </inertia>
        </inertial>
        <collision name='wg-front-left-4_collision'>
          <pose frame=''>0 0 0 0 -0 0</pose>
          <geometry>
            <box>
              <size>0.04 0.001 0.002</size>
            </box>
          </geometry>
          <max_contacts>10</max_contacts>
          <surface>
            <contact>
              <ode/>
            </contact>
            <bounce/>
            <friction>
              <torsional>
                <ode/>
              </torsional>
              <ode/>
            </friction>
          </surface>
        </collision>
        <visual name='wg-front-left-4_visual'>
          <pose frame=''>0 0 0 0 -0 0</pose>
          <geometry>
            <box>
              <size>0.04 0.001 0.002</size>
            </box>
          </geometry>
        </visual>
        <self_collide>0</self_collide>
        <kinematic>0</kinematic>
        <gravity>1</gravity>
      </link>
      <joint name='wg-front-left-4-joint' type='prismatic'>
        <child>wg-front-left-4</child>
        <parent>wh-front-left</parent>
        <axis>
          <xyz>0.309017 0 0.951057</xyz>
          <limit>
            <lower>0</lower>
            <upper>0.008</upper>
            <effort>1</effort>
            <velocity>1</velocity>
          </limit>
          <dynamics>
            <spring_reference>0</spring_reference>
            <spring_stiffness>0</spring_stiffness>
          </dynamics>
          <use_parent_model_frame>1</use_parent_model_frame>
        </axis>
      </joint>
      <link name='wg-front-left-5'>
        <pose frame=''>0.05 -0.0375 0.011 0 -0 0</pose>
        <inertial>
          <pose frame=''>0 0 0 0 -0 0</pose>
          <mass>4e-05</mass>
          <inertia>
            <ixx>1.66667e-11</ixx>
            <ixy>0</ixy>
            <ixz>0</ixz>
            <iyy>5.34667e-09</iyy>
            <iyz>0</iyz>
            <izz>5.33667e-09</izz>
          </inertia>
        </inertial>
        <collision name='wg-front-left-5_collision'>
          <pose frame=''>0 0 0 0 -0 0</pose>
          <geometry>
            <box>
              <size>0.04 0.001 0.002</size>
            </box>
          </geometry>
          <max_contacts>10</max_contacts>
          <surface>
            <contact>
              <ode/>
            </contact>
            <bounce/>
            <friction>
              <torsional>
                <ode/>
              </torsional>
              <ode/>
            </friction>
          </surface>
        </collision>
        <visual name='wg-front-left-5_visual'>
          <pose frame=''>0 0 0 0 -0 0</pose>
          <geometry>
            <box>
              <size>0.04 0.001 0.002</size>
            </box>
          </geometry>
        </visual>
        <self_collide>0</self_collide>
        <kinematic>0</kinematic>
        <gravity>1</gravity>
      </link>
      <joint name='wg-front-left-5-joint' type='prismatic'>
        <child>wg-front-left-5</child>
        <parent>wh-front-left</parent>
        <axis>
          <xyz>1 -0 -0</xyz>
          <limit>
            <lower>0</lower>
            <upper>0.008</upper>
            <effort>1</effort>
            <velocity>1</velocity>
          </limit>
          <dynamics>
            <spring_reference>0</spring_reference>
            <spring_stiffness>0</spring_stiffness>
          </dynamics>
          <use_parent_model_frame>1</use_parent_model_frame>
        </axis>
      </joint>
      <link name='wh-front-right'>
        <pose frame=''>0.05 0.0375 0.011 0 -0 0</pose>
        <inertial>
          <pose frame=''>0 0 0 0 -0 0</pose>
          <mass>0.00314593</mass>
          <inertia>
            <ixx>3.21147e-07</ixx>
            <ixy>0</ixy>
            <ixz>0</ixz>
            <iyy>3.21147e-07</iyy>
            <iyz>0</iyz>
            <izz>6.29185e-07</izz>
          </inertia>
        </inertial>
        <collision name='wh-front-right_collision'>
          <pose frame=''>0 0 0 1.57075 -0 0</pose>
          <geometry>
            <cylinder>
              <length>0.005</length>
              <radius>0.02</radius>
            </cylinder>
          </geometry>
          <max_contacts>10</max_contacts>
          <surface>
            <contact>
              <ode/>
            </contact>
            <bounce/>
            <friction>
              <torsional>
                <ode/>
              </torsional>
              <ode/>
            </friction>
          </surface>
        </collision>
        <visual name='wh-front-right_visual'>
          <pose frame=''>0 0 0 1.57075 -0 0</pose>
          <geometry>
            <cylinder>
              <length>0.005</length>
              <radius>0.02</radius>
            </cylinder>
          </geometry>
        </visual>
        <self_collide>0</self_collide>
        <kinematic>0</kinematic>
        <gravity>1</gravity>
      </link>
      <joint name='ax-front-right' type='revolute'>
        <child>wh-front-right</child>
        <parent>base_link</parent>
        <axis>
          <xyz>0 1 0</xyz>
          <limit>
            <lower>-1e+16</lower>
            <upper>1e+16</upper>
          </limit>
          <dynamics>
            <spring_reference>0</spring_reference>
            <spring_stiffness>0</spring_stiffness>
          </dynamics>
          <use_parent_model_frame>1</use_parent_model_frame>
        </axis>
      </joint>
      <link name='wg-front-right-1'>
        <pose frame=''>0.05 0.0375 0.011 0 1.25664 0</pose>
        <inertial>
          <pose frame=''>0 0 0 0 -0 0</pose>
          <mass>4e-05</mass>
          <inertia>
            <ixx>1.66667e-11</ixx>
            <ixy>0</ixy>
            <ixz>0</ixz>
            <iyy>5.34667e-09</iyy>
            <iyz>0</iyz>
            <izz>5.33667e-09</izz>
          </inertia>
        </inertial>
        <collision name='wg-front-right-1_collision'>
          <pose frame=''>0 0 0 0 -0 0</pose>
          <geometry>
            <box>
              <size>0.04 0.001 0.002</size>
            </box>
          </geometry>
          <max_contacts>10</max_contacts>
          <surface>
            <contact>
              <ode/>
            </contact>
            <bounce/>
            <friction>
              <torsional>
                <ode/>
              </torsional>
              <ode/>
            </friction>
          </surface>
        </collision>
        <visual name='wg-front-right-1_visual'>
          <pose frame=''>0 0 0 0 -0 0</pose>
          <geometry>
            <box>
              <size>0.04 0.001 0.002</size>
            </box>
          </geometry>
        </visual>
        <self_collide>0</self_collide>
        <kinematic>0</kinematic>
        <gravity>1</gravity>
      </link>
      <joint name='wg-front-right-1-joint' type='prismatic'>
        <child>wg-front-right-1</child>
        <parent>wh-front-right</parent>
        <axis>
          <xyz>0.309017 0 -0.951057</xyz>
          <limit>
            <lower>0</lower>
            <upper>0.008</upper>
            <effort>1</effort>
            <velocity>1</velocity>
          </limit>
          <dynamics>
            <spring_reference>0</spring_reference>
            <spring_stiffness>0</spring_stiffness>
          </dynamics>
          <use_parent_model_frame>1</use_parent_model_frame>
        </axis>
      </joint>
      <link name='wg-front-right-2'>
        <pose frame=''>0.05 0.0375 0.011 3.14159 0.628319 3.14159</pose>
        <inertial>
          <pose frame=''>0 0 0 0 -0 0</pose>
          <mass>4e-05</mass>
          <inertia>
            <ixx>1.66667e-11</ixx>
            <ixy>0</ixy>
            <ixz>0</ixz>
            <iyy>5.34667e-09</iyy>
            <iyz>0</iyz>
            <izz>5.33667e-09</izz>
          </inertia>
        </inertial>
        <collision name='wg-front-right-2_collision'>
          <pose frame=''>0 0 0 0 -0 0</pose>
          <geometry>
            <box>
              <size>0.04 0.001 0.002</size>
            </box>
          </geometry>
          <max_contacts>10</max_contacts>
          <surface>
            <contact>
              <ode/>
            </contact>
            <bounce/>
            <friction>
              <torsional>
                <ode/>
              </torsional>
              <ode/>
            </friction>
          </surface>
        </collision>
        <visual name='wg-front-right-2_visual'>
          <pose frame=''>0 0 0 0 -0 0</pose>
          <geometry>
            <box>
              <size>0.04 0.001 0.002</size>
            </box>
          </geometry>
        </visual>
        <self_collide>0</self_collide>
        <kinematic>0</kinematic>
        <gravity>1</gravity>
      </link>
      <joint name='wg-front-right-2-joint' type='prismatic'>
        <child>wg-front-right-2</child>
        <parent>wh-front-right</parent>
        <axis>
          <xyz>-0.809017 0 -0.587785</xyz>
          <limit>
            <lower>0</lower>
            <upper>0.008</upper>
            <effort>1</effort>
            <velocity>1</velocity>
          </limit>
          <dynamics>
            <spring_reference>0</spring_reference>
            <spring_stiffness>0</spring_stiffness>
          </dynamics>
          <use_parent_model_frame>1</use_parent_model_frame>
        </axis>
      </joint>
      <link name='wg-front-right-3'>
        <pose frame=''>0.05 0.0375 0.011 3.14159 -0.628319 -3.14159</pose>
        <inertial>
          <pose frame=''>0 0 0 0 -0 0</pose>
          <mass>4e-05</mass>
          <inertia>
            <ixx>1.66667e-11</ixx>
            <ixy>0</ixy>
            <ixz>0</ixz>
            <iyy>5.34667e-09</iyy>
            <iyz>0</iyz>
            <izz>5.33667e-09</izz>
          </inertia>
        </inertial>
        <collision name='wg-front-right-3_collision'>
          <pose frame=''>0 0 0 0 -0 0</pose>
          <geometry>
            <box>
              <size>0.04 0.001 0.002</size>
            </box>
          </geometry>
          <max_contacts>10</max_contacts>
          <surface>
            <contact>
              <ode/>
            </contact>
            <bounce/>
            <friction>
              <torsional>
                <ode/>
              </torsional>
              <ode/>
            </friction>
          </surface>
        </collision>
        <visual name='wg-front-right-3_visual'>
          <pose frame=''>0 0 0 0 -0 0</pose>
          <geometry>
            <box>
              <size>0.04 0.001 0.002</size>
            </box>
          </geometry>
        </visual>
        <self_collide>0</self_collide>
        <kinematic>0</kinematic>
        <gravity>1</gravity>
      </link>
      <joint name='wg-front-right-3-joint' type='prismatic'>
        <child>wg-front-right-3</child>
        <parent>wh-front-right</parent>
        <axis>
          <xyz>-0.809017 0 0.587785</xyz>
          <limit>
            <lower>0</lower>
            <upper>0.008</upper>
            <effort>1</effort>
            <velocity>1</velocity>
          </limit>
          <dynamics>
            <spring_reference>0</spring_reference>
            <spring_stiffness>0</spring_stiffness>
          </dynamics>
          <use_parent_model_frame>1</use_parent_model_frame>
        </axis>
      </joint>
      <link name='wg-front-right-4'>
        <pose frame=''>0.05 0.0375 0.011 0 -1.25664 0</pose>
        <inertial>
          <pose frame=''>0 0 0 0 -0 0</pose>
          <mass>4e-05</mass>
          <inertia>
            <ixx>1.66667e-11</ixx>
            <ixy>0</ixy>
            <ixz>0</ixz>
            <iyy>5.34667e-09</iyy>
            <iyz>0</iyz>
            <izz>5.33667e-09</izz>
          </inertia>
        </inertial>
        <collision name='wg-front-right-4_collision'>
          <pose frame=''>0 0 0 0 -0 0</pose>
          <geometry>
            <box>
              <size>0.04 0.001 0.002</size>
            </box>
          </geometry>
          <max_contacts>10</max_contacts>
          <surface>
            <contact>
              <ode/>
            </contact>
            <bounce/>
            <friction>
              <torsional>
                <ode/>
              </torsional>
              <ode/>
            </friction>
          </surface>
        </collision>
        <visual name='wg-front-right-4_visual'>
          <pose frame=''>0 0 0 0 -0 0</pose>
          <geometry>
            <box>
              <size>0.04 0.001 0.002</size>
            </box>
          </geometry>
        </visual>
        <self_collide>0</self_collide>
        <kinematic>0</kinematic>
        <gravity>1</gravity>
      </link>
      <joint name='wg-front-right-4-joint' type='prismatic'>
        <child>wg-front-right-4</child>
        <parent>wh-front-right</parent>
        <axis>
          <xyz>0.309017 0 0.951057</xyz>
          <limit>
            <lower>0</lower>
            <upper>0.008</upper>
            <effort>1</effort>
            <velocity>1</velocity>
          </limit>
          <dynamics>
            <spring_reference>0</spring_reference>
            <spring_stiffness>0</spring_stiffness>
          </dynamics>
          <use_parent_model_frame>1</use_parent_model_frame>
        </axis>
      </joint>
      <link name='wg-front-right-5'>
        <pose frame=''>0.05 0.0375 0.011 0 -0 0</pose>
        <inertial>
          <pose frame=''>0 0 0 0 -0 0</pose>
          <mass>4e-05</mass>
          <inertia>
            <ixx>1.66667e-11</ixx>
            <ixy>0</ixy>
            <ixz>0</ixz>
            <iyy>5.34667e-09</iyy>
            <iyz>0</iyz>
            <izz>5.33667e-09</izz>
          </inertia>
        </inertial>
        <collision name='wg-front-right-5_collision'>
          <pose frame=''>0 0 0 0 -0 0</pose>
          <geometry>
            <box>
              <size>0.04 0.001 0.002</size>
            </box>
          </geometry>
          <max_contacts>10</max_contacts>
          <surface>
            <contact>
              <ode/>
            </contact>
            <bounce/>
            <friction>
              <torsional>
                <ode/>
              </torsional>
              <ode/>
            </friction>
          </surface>
        </collision>
        <visual name='wg-front-right-5_visual'>
          <pose frame=''>0 0 0 0 -0 0</pose>
          <geometry>
            <box>
              <size>0.04 0.001 0.002</size>
            </box>
          </geometry>
        </visual>
        <self_collide>0</self_collide>
        <kinematic>0</kinematic>
        <gravity>1</gravity>
      </link>
      <joint name='wg-front-right-5-joint' type='prismatic'>
        <child>wg-front-right-5</child>
        <parent>wh-front-right</parent>
        <axis>
          <xyz>1 -0 -0</xyz>
          <limit>
            <lower>0</lower>
            <upper>0.008</upper>
            <effort>1</effort>
            <velocity>1</velocity>
          </limit>
          <dynamics>
            <spring_reference>0</spring_reference>
            <spring_stiffness>0</spring_stiffness>
          </dynamics>
          <use_parent_model_frame>1</use_parent_model_frame>
        </axis>
      </joint>
      <pose frame=''>0 0 0 0 -0 0</pose>
    </model>
    <state world_name='default'>
      <sim_time>166 272000000</sim_time>
      <real_time>70 679738729</real_time>
      <wall_time>1494194802 746573806</wall_time>
      <iterations>70341</iterations>
      <model name='adabot'>
        <pose frame=''>-0.001131 -0.008598 0.009 3e-06 -1e-06 0.006914</pose>
        <scale>1 1 1</scale>
        <link name='base_link'>
          <pose frame=''>-0.001131 -0.008598 0.009 3e-06 -1e-06 0.006914</pose>
          <velocity>-6.2e-05 0 -2e-06 -2.3e-05 8e-06 -0.000159</velocity>
          <acceleration>0.000972 0.000611 -0.002028 -0.029808 0.016247 -0.060588</acceleration>
          <wrench>0.000119 7.5e-05 -0.000248 0 -0 0</wrench>
        </link>
        <link name='wg-back-left-1'>
          <pose frame=''>-0.050147 -0.046438 0.018485 0.000537 1.12598 0.006894</pose>
          <velocity>-0.00175 -9.6e-05 0.004523 0.332046 -0.068302 -0.777054</velocity>
          <acceleration>-3.45094 -0.113437 9.08426 0.138692 -0.346574 0.540616</acceleration>
          <wrench>-0.000138 -5e-06 0.000363 0 -0 0</wrench>
        </link>
        <link name='wg-back-left-2'>
          <pose frame=''>-0.056676 -0.046483 0.014496 3.14154 0.758677 -3.1347</pose>
          <velocity>-2.4e-05 1e-05 -1e-05 -8.9e-05 -0.004669 -0.000187</velocity>
          <acceleration>0.007252 0.00396 -0.017101 1.66337 -0.61726 2.61257</acceleration>
          <wrench>0 0 -1e-06 0 -0 0</wrench>
        </link>
        <link name='wg-back-left-3'>
          <pose frame=''>-0.05087 -0.046443 0.02 3.14156 -0.497961 -3.13467</pose>
          <velocity>-6.8e-05 8e-06 0 3e-05 -0.004668 -0.000152</velocity>
          <acceleration>-0.000952 0.004049 0.000384 -0.076793 -0.781086 1.42215</acceleration>
          <wrench>0 0 0 0 -0 0</wrench>
        </link>
        <link name='wg-back-left-4'>
          <pose frame=''>-0.05087 -0.046443 0.02 -5e-06 -1.387 0.00692</pose>
          <velocity>-6.8e-05 8e-06 0 3.2e-05 -0.004668 -0.000154</velocity>
          <acceleration>-0.000957 0.004049 0.00038 0.055311 -0.738165 -0.944859</acceleration>
          <wrench>0 0 0 0 -0 0</wrench>
        </link>
        <link name='wg-back-left-5'>
          <pose frame=''>-0.050871 -0.046443 0.02 -1e-06 -0.130358 0.006914</pose>
          <velocity>-2.5e-05 8e-06 6e-06 3.3e-05 -0.004668 -0.000153</velocity>
          <acceleration>-0.01165 0.003976 -0.001016 2.19745 -0.70933 2.14532</acceleration>
          <wrench>0 0 0 0 -0 0</wrench>
        </link>
        <link name='wg-back-right-1'>
          <pose frame=''>-0.050662 0.02856 0.018481 0.000834 1.12536 0.006823</pose>
          <velocity>-0.002539 -0.000135 0.006792 0.427975 -0.103313 -0.997765</velocity>
          <acceleration>-5.25428 -0.155088 13.408 -2.00084 1.16319 2.08659</acceleration>
          <wrench>-0.00021 -6e-06 0.000536 0 -0 0</wrench>
        </link>
        <link name='wg-back-right-2'>
          <pose frame=''>-0.057193 0.028516 0.014493 -3.14053 0.759095 -3.13475</pose>
          <velocity>0.002952 0.000232 0.004224 -0.788349 0.166575 -0.805489</velocity>
          <acceleration>7.79891 0.251803 8.81371 -1.14086 -0.051875 0.385034</acceleration>
          <wrench>0.000312 1e-05 0.000353 0 -0 0</wrench>
        </link>
        <link name='wg-back-right-3'>
          <pose frame=''>-0.051389 0.028555 0.02 -3.14159 -0.497364 -3.13468</pose>
          <velocity>-5.7e-05 8e-06 -2e-06 3.5e-05 0.000677 -0.000145</velocity>
          <acceleration>0.002353 0.004027 -0.002738 -2.67067 0.366312 2.28434</acceleration>
          <wrench>0 0 0 0 -0 0</wrench>
        </link>
        <link name='wg-back-right-4'>
          <pose frame=''>-0.051389 0.028555 0.02 3.7e-05 -1.38759 0.006877</pose>
          <velocity>-5.7e-05 8e-06 -2e-06 1.5e-05 0.000677 -0.000143</velocity>
          <acceleration>0.002342 0.004027 -0.002752 0.328777 0.476668 0.473508</acceleration>
          <wrench>0 0 0 0 -0 0</wrench>
        </link>
        <link name='wg-back-right-5'>
          <pose frame=''>-0.05139 0.028555 0.02 7e-06 -0.130955 0.006913</pose>
          <velocity>0.0002 1e-05 3.2e-05 1.2e-05 0.000677 -0.000142</velocity>
          <acceleration>1.52367 0.014546 0.197641 0.634601 0.431422 -2.69314</acceleration>
          <wrench>6.1e-05 1e-06 8e-06 0 -0 0</wrench>
        </link>
        <link name='wg-front-left-1'>
          <pose frame=''>0.049854 -0.045747 0.018481 -0.000203 1.12546 0.006968</pose>
          <velocity>-0.000419 -6.4e-05 0.000807 0.218126 -0.005863 -0.510803</velocity>
          <acceleration>-0.425988 -0.050345 1.89001 1.22764 -0.361555 0.489984</acceleration>
          <wrench>-1.7e-05 -2e-06 7.6e-05 0 -0 0</wrench>
        </link>
        <link name='wg-front-left-2'>
          <pose frame=''>0.043324 -0.045792 0.014493 3.14155 0.75923 -3.1347</pose>
          <velocity>-3.7e-05 -8e-06 -2.1e-05 0.001625 -0.003859 0.001484</velocity>
          <acceleration>0.003196 -0.00162 -0.009546 2.47859 -1.36759 -0.39138</acceleration>
          <wrench>0 0 0 0 -0 0</wrench>
        </link>
        <link name='wg-front-left-3'>
          <pose frame=''>0.049127 -0.045752 0.02 3.14157 -0.497407 -3.13467</pose>
          <velocity>-6.7e-05 -8e-06 -1e-06 1e-05 -0.003519 -0.000158</velocity>
          <acceleration>-0.000945 -0.001937 -0.001935 -1.51961 -1.30118 -2.63914</acceleration>
          <wrench>0 0 0 0 -0 0</wrench>
        </link>
        <link name='wg-front-left-4'>
          <pose frame=''>0.049127 -0.045752 0.02 -2.2e-05 -1.38755 0.006937</pose>
          <velocity>-6.7e-05 -8e-06 -1e-06 -7e-06 -0.003519 -0.000156</velocity>
          <acceleration>-0.000954 -0.001937 -0.00193 -2.92414 -1.35465 3.02178</acceleration>
          <wrench>0 0 0 0 -0 0</wrench>
        </link>
        <link name='wg-front-left-5'>
          <pose frame=''>0.049127 -0.045752 0.02 -5e-06 -0.130912 0.006915</pose>
          <velocity>-2.5e-05 -8e-06 4e-06 -7e-06 -0.003519 -0.000156</velocity>
          <acceleration>-0.011654 -0.002012 -0.003339 1.24279 -1.36945 -0.714119</acceleration>
          <wrench>0 0 0 0 -0 0</wrench>
        </link>
        <link name='wg-front-right-1'>
          <pose frame=''>0.049341 0.029252 0.018474 -0.000613 1.12461 0.007087</pose>
          <velocity>-0.00016 -1.9e-05 -0.000751 0.089385 0.063357 -0.199996</velocity>
          <acceleration>2.75499 -0.123308 -8.48235 1.33398 0.902108 0.536947</acceleration>
          <wrench>0.00011 -5e-06 -0.000339 0 -0 0</wrench>
        </link>
        <link name='wg-front-right-2'>
          <pose frame=''>0.042812 0.029207 0.014496 3.14115 0.759687 -3.13472</pose>
          <velocity>-0.002822 -0.000119 -0.003425 -0.099762 -0.104122 -0.071296</velocity>
          <acceleration>-4.26905 0.08436 -5.30535 -2.9095 0.232023 -1.50671</acceleration>
          <wrench>-0.000171 3e-06 -0.000212 0 -0 0</wrench>
        </link>
        <link name='wg-front-right-3'>
          <pose frame=''>0.048613 0.029247 0.019998 3.1415 -0.496557 -3.13465</pose>
          <velocity>0.00404 2.1e-05 -0.002221 0.000175 -0.004666 -0.000104</velocity>
          <acceleration>4.10595 0.026606 -2.22211 -0.165097 -1.53392 0.071425</acceleration>
          <wrench>0.000164 1e-06 -8.9e-05 0 -0 0</wrench>
        </link>
        <link name='wg-front-right-4'>
          <pose frame=''>0.048609 0.029247 0.02 -8.8e-05 -1.3884 0.007003</pose>
          <velocity>-5.9e-05 -7e-06 1e-06 0.000199 -0.004666 -0.000109</velocity>
          <acceleration>0.001046 -0.001875 0.002105 -1.84088 -1.5454 2.55372</acceleration>
          <wrench>0 0 0 0 -0 0</wrench>
        </link>
        <link name='wg-front-right-5'>
          <pose frame=''>0.048609 0.029247 0.02 -1.9e-05 -0.131762 0.006914</pose>
          <velocity>-5.9e-05 -7e-06 0 0.000199 -0.004666 -0.000109</velocity>
          <acceleration>0.001056 -0.001876 0.00216 1.99065 -1.56235 -0.593597</acceleration>
          <wrench>0 0 0 0 -0 0</wrench>
        </link>
        <link name='wh-back-left'>
          <pose frame=''>-0.050871 -0.046443 0.02 5.9e-05 -0.130354 0.00691</pose>
          <velocity>-7.3e-05 5e-06 -1e-06 -0.00046 -0.003719 -0.000273</velocity>
          <acceleration>-0.010751 0.003024 -0.001323 -0.173487 -0.606634 -0.23896</acceleration>
          <wrench>-3.4e-05 1e-05 -4e-06 0 -0 0</wrench>
        </link>
        <link name='wh-back-right'>
          <pose frame=''>-0.051389 0.028555 0.02 -5e-05 -0.130954 0.006917</pose>
          <velocity>-3.9e-05 8e-06 -1e-06 -0.000201 -0.001866 -0.000397</velocity>
          <acceleration>0.01589 0.003984 -0.000943 -0.227176 0.872673 -0.247077</acceleration>
          <wrench>5e-05 1.3e-05 -3e-06 0 -0 0</wrench>
        </link>
        <link name='wh-front-left'>
          <pose frame=''>0.049127 -0.045751 0.02 9.8e-05 -0.130908 0.006907</pose>
          <velocity>-6.8e-05 -8e-06 0 3.2e-05 -0.003445 -0.000159</velocity>
          <acceleration>-0.006352 -0.00129 -0.000109 0.044985 -0.355172 -0.135929</acceleration>
          <wrench>-2e-05 -4e-06 0 0 -0 0</wrench>
        </link>
        <link name='wh-front-right'>
          <pose frame=''>0.048609 0.029246 0.02 -7.8e-05 -0.131768 0.006918</pose>
          <velocity>-6.6e-05 -5e-06 0 0.000553 -0.003286 3e-06</velocity>
          <acceleration>-0.005224 -0.00191 0.002161 0.100834 -0.300051 0.062776</acceleration>
          <wrench>-1.6e-05 -6e-06 7e-06 0 -0 0</wrench>
        </link>
      </model>
      <model name='coke_can'>
        <pose frame=''>0.006218 0.66799 -0.003988 -0.01578 0.003494 0.000221</pose>
        <scale>1 1 1</scale>
        <link name='link'>
          <pose frame=''>0.006218 0.66799 -0.003988 -0.01578 0.003494 0.000221</pose>
          <velocity>0 0 0 0 -0 0</velocity>
          <acceleration>-0.452787 0.161724 -0.089413 2.0163 -0.028112 2.59238</acceleration>
          <wrench>-0.176587 0.063072 -0.034871 0 -0 0</wrench>
        </link>
      </model>
      <model name='ground_plane'>
        <pose frame=''>0 0 0 0 -0 0</pose>
        <scale>1 1 1</scale>
        <link name='link'>
          <pose frame=''>0 0 0 0 -0 0</pose>
          <velocity>0 0 0 0 -0 0</velocity>
          <acceleration>0 0 0 0 -0 0</acceleration>
          <wrench>0 0 0 0 -0 0</wrench>
        </link>
      </model>
      <model name='rockySurface'>
        <pose frame=''>1.00133 0.142201 0 0 -0 0</pose>
        <scale>1 1 1</scale>
        <link name='link_0'>
          <pose frame=''>1.00133 0.142201 0 0 -0 0</pose>
          <velocity>0 0 0 0 -0 0</velocity>
          <acceleration>0 0 0 0 -0 0</acceleration>
          <wrench>0 0 0 0 -0 0</wrench>
        </link>
      </model>
      <light name='sun'>
        <pose frame=''>0 0 10 0 -0 0</pose>
      </light>
    </state>
    <model name='rockySurface'>
      <link name='link_0'>
        <pose frame=''>0 0 0 0 -0 0</pose>
        <inertial>
          <mass>1</mass>
          <inertia>
            <ixx>0.166667</ixx>
            <ixy>0</ixy>
            <ixz>0</ixz>
            <iyy>0.166667</iyy>
            <iyz>0</iyz>
            <izz>0.166667</izz>
          </inertia>
        </inertial>
        <visual name='visual'>
          <pose frame=''>0 0 0 0 -0 0</pose>
          <geometry>
            <mesh>
              <uri>model://rockySurface/meshes/rockySurfaceGood.dae</uri>
              <scale>1 1 1</scale>
            </mesh>
          </geometry>
          <material>
            <lighting>1</lighting>
            <script>
              <uri>file://media/materials/scripts/gazebo.material</uri>
              <name>Gazebo/Grey</name>
            </script>
            <ambient>0.3 0.3 0.3 1</ambient>
            <diffuse>0.7 0.7 0.7 1</diffuse>
            <specular>0.01 0.01 0.01 1</specular>
            <emissive>0 0 0 1</emissive>
          </material>
          <cast_shadows>1</cast_shadows>
          <transparency>0</transparency>
        </visual>
        <collision name='collision'>
          <laser_retro>0</laser_retro>
          <max_contacts>10</max_contacts>
          <pose frame=''>0 0 0 0 -0 0</pose>
          <geometry>
            <mesh>
              <uri>model://rockySurface/meshes/rockySurfaceGood.dae</uri>
              <scale>1 1 1</scale>
            </mesh>
          </geometry>
          <surface>
            <friction>
              <ode>
                <mu>1</mu>
                <mu2>1</mu2>
                <fdir1>0 0 0</fdir1>
                <slip1>0</slip1>
                <slip2>0</slip2>
              </ode>
              <torsional>
                <coefficient>1</coefficient>
                <patch_radius>0</patch_radius>
                <surface_radius>0</surface_radius>
                <use_patch_radius>1</use_patch_radius>
                <ode>
                  <slip>0</slip>
                </ode>
              </torsional>
            </friction>
            <bounce>
              <restitution_coefficient>0</restitution_coefficient>
              <threshold>1e+06</threshold>
            </bounce>
            <contact>
              <collide_without_contact>0</collide_without_contact>
              <collide_without_contact_bitmask>1</collide_without_contact_bitmask>
              <collide_bitmask>1</collide_bitmask>
              <ode>
                <soft_cfm>0</soft_cfm>
                <soft_erp>0.2</soft_erp>
                <kp>1e+13</kp>
                <kd>1</kd>
                <max_vel>0.01</max_vel>
                <min_depth>0</min_depth>
              </ode>
              <bullet>
                <split_impulse>1</split_impulse>
                <split_impulse_penetration_threshold>-0.01</split_impulse_penetration_threshold>
                <soft_cfm>0</soft_cfm>
                <soft_erp>0.2</soft_erp>
                <kp>1e+13</kp>
                <kd>1</kd>
              </bullet>
            </contact>
          </surface>
        </collision>
        <self_collide>0</self_collide>
        <kinematic>0</kinematic>
      </link>
      <static>1</static>
      <allow_auto_disable>1</allow_auto_disable>
      <pose frame=''>1.00133 0.142201 0 0 -0 0</pose>
    </model>
    <model name='coke_can'>
      <link name='link'>
        <inertial>
          <pose frame=''>-0.01 -0.012 0.15 0 -0 0</pose>
          <mass>0.39</mass>
          <inertia>
            <ixx>0.00058</ixx>
            <ixy>0</ixy>
            <ixz>0</ixz>
            <iyy>0.00058</iyy>
            <iyz>0</iyz>
            <izz>0.00019</izz>
          </inertia>
        </inertial>
        <collision name='collision'>
          <pose frame=''>0 0 -0.46 0 -0 0</pose>
          <geometry>
            <mesh>
              <uri>model://coke_can/meshes/coke_can.dae</uri>
              <scale>1 1 1</scale>
            </mesh>
          </geometry>
          <surface>
            <friction>
              <ode>
                <mu>1</mu>
                <mu2>1</mu2>
              </ode>
              <torsional>
                <ode/>
              </torsional>
            </friction>
            <contact>
              <ode>
                <kp>1e+07</kp>
                <kd>1</kd>
                <min_depth>0.001</min_depth>
                <max_vel>0.1</max_vel>
              </ode>
            </contact>
            <bounce/>
          </surface>
          <max_contacts>10</max_contacts>
        </collision>
        <visual name='visual'>
          <pose frame=''>0 0 -0.46 0 -0 0</pose>
          <geometry>
            <mesh>
              <uri>model://coke_can/meshes/coke_can.dae</uri>
              <scale>1 1 1</scale>
            </mesh>
          </geometry>
        </visual>
        <self_collide>0</self_collide>
        <kinematic>0</kinematic>
      </link>
      <pose frame=''>0.006231 0.668046 0 0 -0 0</pose>
    </model>
  </world>
</sdf>
