<sdf version='1.6'>
  <world name='default'>
    <model name='ground_plane'>
      <static>1</static>
      <link name='link'>
        <collision name='collision'>
          <geometry>
            <plane>
              <normal>0 0 1</normal>
              <size>100 100</size>
            </plane>
          </geometry>
          <surface>
            <friction>
              <ode>
                <mu>100</mu>
                <mu2>50</mu2>
              </ode>
              <torsional>
                <ode/>
              </torsional>
            </friction>
            <contact>
              <ode/>
            </contact>
            <bounce/>
          </surface>
          <max_contacts>10</max_contacts>
        </collision>
        <visual name='visual'>
          <cast_shadows>0</cast_shadows>
          <geometry>
            <plane>
              <normal>0 0 1</normal>
              <size>100 100</size>
            </plane>
          </geometry>
          <material>
            <script>
              <uri>file://media/materials/scripts/gazebo.material</uri>
              <name>Gazebo/Grey</name>
            </script>
          </material>
        </visual>
        <self_collide>0</self_collide>
        <kinematic>0</kinematic>
        <gravity>1</gravity>
      </link>
    </model>
    <light name='sun' type='directional'>
      <cast_shadows>1</cast_shadows>
      <pose frame=''>0 0 10 0 -0 0</pose>
      <diffuse>0.8 0.8 0.8 1</diffuse>
      <specular>0.1 0.1 0.1 1</specular>
      <attenuation>
        <range>1000</range>
        <constant>0.9</constant>
        <linear>0.01</linear>
        <quadratic>0.001</quadratic>
      </attenuation>
      <direction>-0.5 0.5 -1</direction>
    </light>
    <gui fullscreen='0'>
      <camera name='user_camera'>
        <pose frame=''>4.99167 0.331362 1.45588 0 0.199643 3.13619</pose>
        <view_controller>orbit</view_controller>
        <projection_type>perspective</projection_type>
      </camera>
    </gui>
    <gravity>0 0 -9.8</gravity>
    <magnetic_field>6e-06 2.3e-05 -4.2e-05</magnetic_field>
    <atmosphere type='adiabatic'/>
    <physics name='default_physics' default='0' type='ode'>
      <max_step_size>0.001</max_step_size>
      <real_time_factor>1</real_time_factor>
      <real_time_update_rate>1000</real_time_update_rate>
    </physics>
    <scene>
      <ambient>0.4 0.4 0.4 1</ambient>
      <background>0.7 0.7 0.7 1</background>
      <shadows>1</shadows>
    </scene>
    <spherical_coordinates>
      <surface_model>EARTH_WGS84</surface_model>
      <latitude_deg>0</latitude_deg>
      <longitude_deg>0</longitude_deg>
      <elevation>0</elevation>
      <heading_deg>0</heading_deg>
    </spherical_coordinates>
    <model name='adabot'>
      <link name='base_link'>
        <pose frame=''>0 0 0 0 -0 0</pose>
        <inertial>
          <pose frame=''>0 0 0 0 -0 0</pose>
          <mass>0.1225</mass>
          <inertia>
            <ixx>6.2526e-05</ixx>
            <ixy>0</ixy>
            <ixz>0</ixz>
            <iyy>0.000114589</iyy>
            <iyz>0</iyz>
            <izz>0.000152104</izz>
          </inertia>
        </inertial>
        <collision name='base_link_collision'>
          <pose frame=''>0 0 0.011 0 -0 0</pose>
          <geometry>
            <box>
              <size>0.1 0.07 0.035</size>
            </box>
          </geometry>
          <max_contacts>10</max_contacts>
          <surface>
            <contact>
              <ode/>
            </contact>
            <bounce/>
            <friction>
              <torsional>
                <ode/>
              </torsional>
              <ode/>
            </friction>
          </surface>
        </collision>
        <visual name='base_link_visual'>
          <pose frame=''>0 0 0.011 0 -0 0</pose>
          <geometry>
            <box>
              <size>0.1 0.07 0.035</size>
            </box>
          </geometry>
        </visual>
        <self_collide>0</self_collide>
        <kinematic>0</kinematic>
        <gravity>1</gravity>
      </link>
      <link name='wh-back-left'>
        <pose frame=''>-0.05 -0.0375 0.011 0 -0 0</pose>
        <inertial>
          <pose frame=''>0 0 0 0 -0 0</pose>
          <mass>0.00314593</mass>
          <inertia>
            <ixx>3.21147e-07</ixx>
            <ixy>0</ixy>
            <ixz>0</ixz>
            <iyy>3.21147e-07</iyy>
            <iyz>0</iyz>
            <izz>6.29185e-07</izz>
          </inertia>
        </inertial>
        <collision name='wh-back-left_collision'>
          <pose frame=''>0 0 0 1.57075 -0 0</pose>
          <geometry>
            <cylinder>
              <length>0.005</length>
              <radius>0.02</radius>
            </cylinder>
          </geometry>
          <max_contacts>10</max_contacts>
          <surface>
            <contact>
              <ode/>
            </contact>
            <bounce/>
            <friction>
              <torsional>
                <ode/>
              </torsional>
              <ode/>
            </friction>
          </surface>
        </collision>
        <visual name='wh-back-left_visual'>
          <pose frame=''>0 0 0 1.57075 -0 0</pose>
          <geometry>
            <cylinder>
              <length>0.005</length>
              <radius>0.02</radius>
            </cylinder>
          </geometry>
        </visual>
        <self_collide>0</self_collide>
        <kinematic>0</kinematic>
        <gravity>1</gravity>
      </link>
      <joint name='ax-back-left' type='revolute'>
        <child>wh-back-left</child>
        <parent>base_link</parent>
        <axis>
          <xyz>0 1 0</xyz>
          <limit>
            <lower>-1e+16</lower>
            <upper>1e+16</upper>
          </limit>
          <dynamics>
            <spring_reference>0</spring_reference>
            <spring_stiffness>0</spring_stiffness>
          </dynamics>
          <use_parent_model_frame>1</use_parent_model_frame>
        </axis>
      </joint>
      <link name='wg-back-left-1'>
        <pose frame=''>-0.05 -0.0375 0.011 0 1.25664 0</pose>
        <inertial>
          <pose frame=''>0 0 0 0 -0 0</pose>
          <mass>4e-05</mass>
          <inertia>
            <ixx>1.66667e-11</ixx>
            <ixy>0</ixy>
            <ixz>0</ixz>
            <iyy>5.34667e-09</iyy>
            <iyz>0</iyz>
            <izz>5.33667e-09</izz>
          </inertia>
        </inertial>
        <collision name='wg-back-left-1_collision'>
          <pose frame=''>0 0 0 0 -0 0</pose>
          <geometry>
            <box>
              <size>0.04 0.001 0.002</size>
            </box>
          </geometry>
          <max_contacts>10</max_contacts>
          <surface>
            <contact>
              <ode/>
            </contact>
            <bounce/>
            <friction>
              <torsional>
                <ode/>
              </torsional>
              <ode/>
            </friction>
          </surface>
        </collision>
        <visual name='wg-back-left-1_visual'>
          <pose frame=''>0 0 0 0 -0 0</pose>
          <geometry>
            <box>
              <size>0.04 0.001 0.002</size>
            </box>
          </geometry>
        </visual>
        <self_collide>0</self_collide>
        <kinematic>0</kinematic>
        <gravity>1</gravity>
      </link>
      <joint name='wg-back-left-1-joint' type='prismatic'>
        <child>wg-back-left-1</child>
        <parent>wh-back-left</parent>
        <axis>
          <xyz>0.309017 0 -0.951057</xyz>
          <limit>
            <lower>0</lower>
            <upper>0.008</upper>
            <effort>1</effort>
            <velocity>1</velocity>
          </limit>
          <dynamics>
            <spring_reference>0</spring_reference>
            <spring_stiffness>0</spring_stiffness>
          </dynamics>
          <use_parent_model_frame>1</use_parent_model_frame>
        </axis>
      </joint>
      <link name='wg-back-left-2'>
        <pose frame=''>-0.05 -0.0375 0.011 3.14159 0.628319 3.14159</pose>
        <inertial>
          <pose frame=''>0 0 0 0 -0 0</pose>
          <mass>4e-05</mass>
          <inertia>
            <ixx>1.66667e-11</ixx>
            <ixy>0</ixy>
            <ixz>0</ixz>
            <iyy>5.34667e-09</iyy>
            <iyz>0</iyz>
            <izz>5.33667e-09</izz>
          </inertia>
        </inertial>
        <collision name='wg-back-left-2_collision'>
          <pose frame=''>0 0 0 0 -0 0</pose>
          <geometry>
            <box>
              <size>0.04 0.001 0.002</size>
            </box>
          </geometry>
          <max_contacts>10</max_contacts>
          <surface>
            <contact>
              <ode/>
            </contact>
            <bounce/>
            <friction>
              <torsional>
                <ode/>
              </torsional>
              <ode/>
            </friction>
          </surface>
        </collision>
        <visual name='wg-back-left-2_visual'>
          <pose frame=''>0 0 0 0 -0 0</pose>
          <geometry>
            <box>
              <size>0.04 0.001 0.002</size>
            </box>
          </geometry>
        </visual>
        <self_collide>0</self_collide>
        <kinematic>0</kinematic>
        <gravity>1</gravity>
      </link>
      <joint name='wg-back-left-2-joint' type='prismatic'>
        <child>wg-back-left-2</child>
        <parent>wh-back-left</parent>
        <axis>
          <xyz>-0.809017 0 -0.587785</xyz>
          <limit>
            <lower>0</lower>
            <upper>0.008</upper>
            <effort>1</effort>
            <velocity>1</velocity>
          </limit>
          <dynamics>
            <spring_reference>0</spring_reference>
            <spring_stiffness>0</spring_stiffness>
          </dynamics>
          <use_parent_model_frame>1</use_parent_model_frame>
        </axis>
      </joint>
      <link name='wg-back-left-3'>
        <pose frame=''>-0.05 -0.0375 0.011 3.14159 -0.628319 -3.14159</pose>
        <inertial>
          <pose frame=''>0 0 0 0 -0 0</pose>
          <mass>4e-05</mass>
          <inertia>
            <ixx>1.66667e-11</ixx>
            <ixy>0</ixy>
            <ixz>0</ixz>
            <iyy>5.34667e-09</iyy>
            <iyz>0</iyz>
            <izz>5.33667e-09</izz>
          </inertia>
        </inertial>
        <collision name='wg-back-left-3_collision'>
          <pose frame=''>0 0 0 0 -0 0</pose>
          <geometry>
            <box>
              <size>0.04 0.001 0.002</size>
            </box>
          </geometry>
          <max_contacts>10</max_contacts>
          <surface>
            <contact>
              <ode/>
            </contact>
            <bounce/>
            <friction>
              <torsional>
                <ode/>
              </torsional>
              <ode/>
            </friction>
          </surface>
        </collision>
        <visual name='wg-back-left-3_visual'>
          <pose frame=''>0 0 0 0 -0 0</pose>
          <geometry>
            <box>
              <size>0.04 0.001 0.002</size>
            </box>
          </geometry>
        </visual>
        <self_collide>0</self_collide>
        <kinematic>0</kinematic>
        <gravity>1</gravity>
      </link>
      <joint name='wg-back-left-3-joint' type='prismatic'>
        <child>wg-back-left-3</child>
        <parent>wh-back-left</parent>
        <axis>
          <xyz>-0.809017 0 0.587785</xyz>
          <limit>
            <lower>0</lower>
            <upper>0.008</upper>
            <effort>1</effort>
            <velocity>1</velocity>
          </limit>
          <dynamics>
            <spring_reference>0</spring_reference>
            <spring_stiffness>0</spring_stiffness>
          </dynamics>
          <use_parent_model_frame>1</use_parent_model_frame>
        </axis>
      </joint>
      <link name='wg-back-left-4'>
        <pose frame=''>-0.05 -0.0375 0.011 0 -1.25664 0</pose>
        <inertial>
          <pose frame=''>0 0 0 0 -0 0</pose>
          <mass>4e-05</mass>
          <inertia>
            <ixx>1.66667e-11</ixx>
            <ixy>0</ixy>
            <ixz>0</ixz>
            <iyy>5.34667e-09</iyy>
            <iyz>0</iyz>
            <izz>5.33667e-09</izz>
          </inertia>
        </inertial>
        <collision name='wg-back-left-4_collision'>
          <pose frame=''>0 0 0 0 -0 0</pose>
          <geometry>
            <box>
              <size>0.04 0.001 0.002</size>
            </box>
          </geometry>
          <max_contacts>10</max_contacts>
          <surface>
            <contact>
              <ode/>
            </contact>
            <bounce/>
            <friction>
              <torsional>
                <ode/>
              </torsional>
              <ode/>
            </friction>
          </surface>
        </collision>
        <visual name='wg-back-left-4_visual'>
          <pose frame=''>0 0 0 0 -0 0</pose>
          <geometry>
            <box>
              <size>0.04 0.001 0.002</size>
            </box>
          </geometry>
        </visual>
        <self_collide>0</self_collide>
        <kinematic>0</kinematic>
        <gravity>1</gravity>
      </link>
      <joint name='wg-back-left-4-joint' type='prismatic'>
        <child>wg-back-left-4</child>
        <parent>wh-back-left</parent>
        <axis>
          <xyz>0.309017 0 0.951057</xyz>
          <limit>
            <lower>0</lower>
            <upper>0.008</upper>
            <effort>1</effort>
            <velocity>1</velocity>
          </limit>
          <dynamics>
            <spring_reference>0</spring_reference>
            <spring_stiffness>0</spring_stiffness>
          </dynamics>
          <use_parent_model_frame>1</use_parent_model_frame>
        </axis>
      </joint>
      <link name='wg-back-left-5'>
        <pose frame=''>-0.05 -0.0375 0.011 0 -0 0</pose>
        <inertial>
          <pose frame=''>0 0 0 0 -0 0</pose>
          <mass>4e-05</mass>
          <inertia>
            <ixx>1.66667e-11</ixx>
            <ixy>0</ixy>
            <ixz>0</ixz>
            <iyy>5.34667e-09</iyy>
            <iyz>0</iyz>
            <izz>5.33667e-09</izz>
          </inertia>
        </inertial>
        <collision name='wg-back-left-5_collision'>
          <pose frame=''>0 0 0 0 -0 0</pose>
          <geometry>
            <box>
              <size>0.04 0.001 0.002</size>
            </box>
          </geometry>
          <max_contacts>10</max_contacts>
          <surface>
            <contact>
              <ode/>
            </contact>
            <bounce/>
            <friction>
              <torsional>
                <ode/>
              </torsional>
              <ode/>
            </friction>
          </surface>
        </collision>
        <visual name='wg-back-left-5_visual'>
          <pose frame=''>0 0 0 0 -0 0</pose>
          <geometry>
            <box>
              <size>0.04 0.001 0.002</size>
            </box>
          </geometry>
        </visual>
        <self_collide>0</self_collide>
        <kinematic>0</kinematic>
        <gravity>1</gravity>
      </link>
      <joint name='wg-back-left-5-joint' type='prismatic'>
        <child>wg-back-left-5</child>
        <parent>wh-back-left</parent>
        <axis>
          <xyz>1 -0 -0</xyz>
          <limit>
            <lower>0</lower>
            <upper>0.008</upper>
            <effort>1</effort>
            <velocity>1</velocity>
          </limit>
          <dynamics>
            <spring_reference>0</spring_reference>
            <spring_stiffness>0</spring_stiffness>
          </dynamics>
          <use_parent_model_frame>1</use_parent_model_frame>
        </axis>
      </joint>
      <link name='wh-back-right'>
        <pose frame=''>-0.05 0.0375 0.011 0 -0 0</pose>
        <inertial>
          <pose frame=''>0 0 0 0 -0 0</pose>
          <mass>0.00314593</mass>
          <inertia>
            <ixx>3.21147e-07</ixx>
            <ixy>0</ixy>
            <ixz>0</ixz>
            <iyy>3.21147e-07</iyy>
            <iyz>0</iyz>
            <izz>6.29185e-07</izz>
          </inertia>
        </inertial>
        <collision name='wh-back-right_collision'>
          <pose frame=''>0 0 0 1.57075 -0 0</pose>
          <geometry>
            <cylinder>
              <length>0.005</length>
              <radius>0.02</radius>
            </cylinder>
          </geometry>
          <max_contacts>10</max_contacts>
          <surface>
            <contact>
              <ode/>
            </contact>
            <bounce/>
            <friction>
              <torsional>
                <ode/>
              </torsional>
              <ode/>
            </friction>
          </surface>
        </collision>
        <visual name='wh-back-right_visual'>
          <pose frame=''>0 0 0 1.57075 -0 0</pose>
          <geometry>
            <cylinder>
              <length>0.005</length>
              <radius>0.02</radius>
            </cylinder>
          </geometry>
        </visual>
        <self_collide>0</self_collide>
        <kinematic>0</kinematic>
        <gravity>1</gravity>
      </link>
      <joint name='ax-back-right' type='revolute'>
        <child>wh-back-right</child>
        <parent>base_link</parent>
        <axis>
          <xyz>0 1 0</xyz>
          <limit>
            <lower>-1e+16</lower>
            <upper>1e+16</upper>
          </limit>
          <dynamics>
            <spring_reference>0</spring_reference>
            <spring_stiffness>0</spring_stiffness>
          </dynamics>
          <use_parent_model_frame>1</use_parent_model_frame>
        </axis>
      </joint>
      <link name='wg-back-right-1'>
        <pose frame=''>-0.05 0.0375 0.011 0 1.25664 0</pose>
        <inertial>
          <pose frame=''>0 0 0 0 -0 0</pose>
          <mass>4e-05</mass>
          <inertia>
            <ixx>1.66667e-11</ixx>
            <ixy>0</ixy>
            <ixz>0</ixz>
            <iyy>5.34667e-09</iyy>
            <iyz>0</iyz>
            <izz>5.33667e-09</izz>
          </inertia>
        </inertial>
        <collision name='wg-back-right-1_collision'>
          <pose frame=''>0 0 0 0 -0 0</pose>
          <geometry>
            <box>
              <size>0.04 0.001 0.002</size>
            </box>
          </geometry>
          <max_contacts>10</max_contacts>
          <surface>
            <contact>
              <ode/>
            </contact>
            <bounce/>
            <friction>
              <torsional>
                <ode/>
              </torsional>
              <ode/>
            </friction>
          </surface>
        </collision>
        <visual name='wg-back-right-1_visual'>
          <pose frame=''>0 0 0 0 -0 0</pose>
          <geometry>
            <box>
              <size>0.04 0.001 0.002</size>
            </box>
          </geometry>
        </visual>
        <self_collide>0</self_collide>
        <kinematic>0</kinematic>
        <gravity>1</gravity>
      </link>
      <joint name='wg-back-right-1-joint' type='prismatic'>
        <child>wg-back-right-1</child>
        <parent>wh-back-right</parent>
        <axis>
          <xyz>0.309017 0 -0.951057</xyz>
          <limit>
            <lower>0</lower>
            <upper>0.008</upper>
            <effort>1</effort>
            <velocity>1</velocity>
          </limit>
          <dynamics>
            <spring_reference>0</spring_reference>
            <spring_stiffness>0</spring_stiffness>
          </dynamics>
          <use_parent_model_frame>1</use_parent_model_frame>
        </axis>
      </joint>
      <link name='wg-back-right-2'>
        <pose frame=''>-0.05 0.0375 0.011 3.14159 0.628319 3.14159</pose>
        <inertial>
          <pose frame=''>0 0 0 0 -0 0</pose>
          <mass>4e-05</mass>
          <inertia>
            <ixx>1.66667e-11</ixx>
            <ixy>0</ixy>
            <ixz>0</ixz>
            <iyy>5.34667e-09</iyy>
            <iyz>0</iyz>
            <izz>5.33667e-09</izz>
          </inertia>
        </inertial>
        <collision name='wg-back-right-2_collision'>
          <pose frame=''>0 0 0 0 -0 0</pose>
          <geometry>
            <box>
              <size>0.04 0.001 0.002</size>
            </box>
          </geometry>
          <max_contacts>10</max_contacts>
          <surface>
            <contact>
              <ode/>
            </contact>
            <bounce/>
            <friction>
              <torsional>
                <ode/>
              </torsional>
              <ode/>
            </friction>
          </surface>
        </collision>
        <visual name='wg-back-right-2_visual'>
          <pose frame=''>0 0 0 0 -0 0</pose>
          <geometry>
            <box>
              <size>0.04 0.001 0.002</size>
            </box>
          </geometry>
        </visual>
        <self_collide>0</self_collide>
        <kinematic>0</kinematic>
        <gravity>1</gravity>
      </link>
      <joint name='wg-back-right-2-joint' type='prismatic'>
        <child>wg-back-right-2</child>
        <parent>wh-back-right</parent>
        <axis>
          <xyz>-0.809017 0 -0.587785</xyz>
          <limit>
            <lower>0</lower>
            <upper>0.008</upper>
            <effort>1</effort>
            <velocity>1</velocity>
          </limit>
          <dynamics>
            <spring_reference>0</spring_reference>
            <spring_stiffness>0</spring_stiffness>
          </dynamics>
          <use_parent_model_frame>1</use_parent_model_frame>
        </axis>
      </joint>
      <link name='wg-back-right-3'>
        <pose frame=''>-0.05 0.0375 0.011 3.14159 -0.628319 -3.14159</pose>
        <inertial>
          <pose frame=''>0 0 0 0 -0 0</pose>
          <mass>4e-05</mass>
          <inertia>
            <ixx>1.66667e-11</ixx>
            <ixy>0</ixy>
            <ixz>0</ixz>
            <iyy>5.34667e-09</iyy>
            <iyz>0</iyz>
            <izz>5.33667e-09</izz>
          </inertia>
        </inertial>
        <collision name='wg-back-right-3_collision'>
          <pose frame=''>0 0 0 0 -0 0</pose>
          <geometry>
            <box>
              <size>0.04 0.001 0.002</size>
            </box>
          </geometry>
          <max_contacts>10</max_contacts>
          <surface>
            <contact>
              <ode/>
            </contact>
            <bounce/>
            <friction>
              <torsional>
                <ode/>
              </torsional>
              <ode/>
            </friction>
          </surface>
        </collision>
        <visual name='wg-back-right-3_visual'>
          <pose frame=''>0 0 0 0 -0 0</pose>
          <geometry>
            <box>
              <size>0.04 0.001 0.002</size>
            </box>
          </geometry>
        </visual>
        <self_collide>0</self_collide>
        <kinematic>0</kinematic>
        <gravity>1</gravity>
      </link>
      <joint name='wg-back-right-3-joint' type='prismatic'>
        <child>wg-back-right-3</child>
        <parent>wh-back-right</parent>
        <axis>
          <xyz>-0.809017 0 0.587785</xyz>
          <limit>
            <lower>0</lower>
            <upper>0.008</upper>
            <effort>1</effort>
            <velocity>1</velocity>
          </limit>
          <dynamics>
            <spring_reference>0</spring_reference>
            <spring_stiffness>0</spring_stiffness>
          </dynamics>
          <use_parent_model_frame>1</use_parent_model_frame>
        </axis>
      </joint>
      <link name='wg-back-right-4'>
        <pose frame=''>-0.05 0.0375 0.011 0 -1.25664 0</pose>
        <inertial>
          <pose frame=''>0 0 0 0 -0 0</pose>
          <mass>4e-05</mass>
          <inertia>
            <ixx>1.66667e-11</ixx>
            <ixy>0</ixy>
            <ixz>0</ixz>
            <iyy>5.34667e-09</iyy>
            <iyz>0</iyz>
            <izz>5.33667e-09</izz>
          </inertia>
        </inertial>
        <collision name='wg-back-right-4_collision'>
          <pose frame=''>0 0 0 0 -0 0</pose>
          <geometry>
            <box>
              <size>0.04 0.001 0.002</size>
            </box>
          </geometry>
          <max_contacts>10</max_contacts>
          <surface>
            <contact>
              <ode/>
            </contact>
            <bounce/>
            <friction>
              <torsional>
                <ode/>
              </torsional>
              <ode/>
            </friction>
          </surface>
        </collision>
        <visual name='wg-back-right-4_visual'>
          <pose frame=''>0 0 0 0 -0 0</pose>
          <geometry>
            <box>
              <size>0.04 0.001 0.002</size>
            </box>
          </geometry>
        </visual>
        <self_collide>0</self_collide>
        <kinematic>0</kinematic>
        <gravity>1</gravity>
      </link>
      <joint name='wg-back-right-4-joint' type='prismatic'>
        <child>wg-back-right-4</child>
        <parent>wh-back-right</parent>
        <axis>
          <xyz>0.309017 0 0.951057</xyz>
          <limit>
            <lower>0</lower>
            <upper>0.008</upper>
            <effort>1</effort>
            <velocity>1</velocity>
          </limit>
          <dynamics>
            <spring_reference>0</spring_reference>
            <spring_stiffness>0</spring_stiffness>
          </dynamics>
          <use_parent_model_frame>1</use_parent_model_frame>
        </axis>
      </joint>
      <link name='wg-back-right-5'>
        <pose frame=''>-0.05 0.0375 0.011 0 -0 0</pose>
        <inertial>
          <pose frame=''>0 0 0 0 -0 0</pose>
          <mass>4e-05</mass>
          <inertia>
            <ixx>1.66667e-11</ixx>
            <ixy>0</ixy>
            <ixz>0</ixz>
            <iyy>5.34667e-09</iyy>
            <iyz>0</iyz>
            <izz>5.33667e-09</izz>
          </inertia>
        </inertial>
        <collision name='wg-back-right-5_collision'>
          <pose frame=''>0 0 0 0 -0 0</pose>
          <geometry>
            <box>
              <size>0.04 0.001 0.002</size>
            </box>
          </geometry>
          <max_contacts>10</max_contacts>
          <surface>
            <contact>
              <ode/>
            </contact>
            <bounce/>
            <friction>
              <torsional>
                <ode/>
              </torsional>
              <ode/>
            </friction>
          </surface>
        </collision>
        <visual name='wg-back-right-5_visual'>
          <pose frame=''>0 0 0 0 -0 0</pose>
          <geometry>
            <box>
              <size>0.04 0.001 0.002</size>
            </box>
          </geometry>
        </visual>
        <self_collide>0</self_collide>
        <kinematic>0</kinematic>
        <gravity>1</gravity>
      </link>
      <joint name='wg-back-right-5-joint' type='prismatic'>
        <child>wg-back-right-5</child>
        <parent>wh-back-right</parent>
        <axis>
          <xyz>1 -0 -0</xyz>
          <limit>
            <lower>0</lower>
            <upper>0.008</upper>
            <effort>1</effort>
            <velocity>1</velocity>
          </limit>
          <dynamics>
            <spring_reference>0</spring_reference>
            <spring_stiffness>0</spring_stiffness>
          </dynamics>
          <use_parent_model_frame>1</use_parent_model_frame>
        </axis>
      </joint>
      <link name='wh-front-left'>
        <pose frame=''>0.05 -0.0375 0.011 0 -0 0</pose>
        <inertial>
          <pose frame=''>0 0 0 0 -0 0</pose>
          <mass>0.00314593</mass>
          <inertia>
            <ixx>3.21147e-07</ixx>
            <ixy>0</ixy>
            <ixz>0</ixz>
            <iyy>3.21147e-07</iyy>
            <iyz>0</iyz>
            <izz>6.29185e-07</izz>
          </inertia>
        </inertial>
        <collision name='wh-front-left_collision'>
          <pose frame=''>0 0 0 1.57075 -0 0</pose>
          <geometry>
            <cylinder>
              <length>0.005</length>
              <radius>0.02</radius>
            </cylinder>
          </geometry>
          <max_contacts>10</max_contacts>
          <surface>
            <contact>
              <ode/>
            </contact>
            <bounce/>
            <friction>
              <torsional>
                <ode/>
              </torsional>
              <ode/>
            </friction>
          </surface>
        </collision>
        <visual name='wh-front-left_visual'>
          <pose frame=''>0 0 0 1.57075 -0 0</pose>
          <geometry>
            <cylinder>
              <length>0.005</length>
              <radius>0.02</radius>
            </cylinder>
          </geometry>
        </visual>
        <self_collide>0</self_collide>
        <kinematic>0</kinematic>
        <gravity>1</gravity>
      </link>
      <joint name='ax-front-left' type='revolute'>
        <child>wh-front-left</child>
        <parent>base_link</parent>
        <axis>
          <xyz>0 1 0</xyz>
          <limit>
            <lower>-1e+16</lower>
            <upper>1e+16</upper>
          </limit>
          <dynamics>
            <spring_reference>0</spring_reference>
            <spring_stiffness>0</spring_stiffness>
          </dynamics>
          <use_parent_model_frame>1</use_parent_model_frame>
        </axis>
      </joint>
      <link name='wg-front-left-1'>
        <pose frame=''>0.05 -0.0375 0.011 0 1.25664 0</pose>
        <inertial>
          <pose frame=''>0 0 0 0 -0 0</pose>
          <mass>4e-05</mass>
          <inertia>
            <ixx>1.66667e-11</ixx>
            <ixy>0</ixy>
            <ixz>0</ixz>
            <iyy>5.34667e-09</iyy>
            <iyz>0</iyz>
            <izz>5.33667e-09</izz>
          </inertia>
        </inertial>
        <collision name='wg-front-left-1_collision'>
          <pose frame=''>0 0 0 0 -0 0</pose>
          <geometry>
            <box>
              <size>0.04 0.001 0.002</size>
            </box>
          </geometry>
          <max_contacts>10</max_contacts>
          <surface>
            <contact>
              <ode/>
            </contact>
            <bounce/>
            <friction>
              <torsional>
                <ode/>
              </torsional>
              <ode/>
            </friction>
          </surface>
        </collision>
        <visual name='wg-front-left-1_visual'>
          <pose frame=''>0 0 0 0 -0 0</pose>
          <geometry>
            <box>
              <size>0.04 0.001 0.002</size>
            </box>
          </geometry>
        </visual>
        <self_collide>0</self_collide>
        <kinematic>0</kinematic>
        <gravity>1</gravity>
      </link>
      <joint name='wg-front-left-1-joint' type='prismatic'>
        <child>wg-front-left-1</child>
        <parent>wh-front-left</parent>
        <axis>
          <xyz>0.309017 0 -0.951057</xyz>
          <limit>
            <lower>0</lower>
            <upper>0.008</upper>
            <effort>1</effort>
            <velocity>1</velocity>
          </limit>
          <dynamics>
            <spring_reference>0</spring_reference>
            <spring_stiffness>0</spring_stiffness>
          </dynamics>
          <use_parent_model_frame>1</use_parent_model_frame>
        </axis>
      </joint>
      <link name='wg-front-left-2'>
        <pose frame=''>0.05 -0.0375 0.011 3.14159 0.628319 3.14159</pose>
        <inertial>
          <pose frame=''>0 0 0 0 -0 0</pose>
          <mass>4e-05</mass>
          <inertia>
            <ixx>1.66667e-11</ixx>
            <ixy>0</ixy>
            <ixz>0</ixz>
            <iyy>5.34667e-09</iyy>
            <iyz>0</iyz>
            <izz>5.33667e-09</izz>
          </inertia>
        </inertial>
        <collision name='wg-front-left-2_collision'>
          <pose frame=''>0 0 0 0 -0 0</pose>
          <geometry>
            <box>
              <size>0.04 0.001 0.002</size>
            </box>
          </geometry>
          <max_contacts>10</max_contacts>
          <surface>
            <contact>
              <ode/>
            </contact>
            <bounce/>
            <friction>
              <torsional>
                <ode/>
              </torsional>
              <ode/>
            </friction>
          </surface>
        </collision>
        <visual name='wg-front-left-2_visual'>
          <pose frame=''>0 0 0 0 -0 0</pose>
          <geometry>
            <box>
              <size>0.04 0.001 0.002</size>
            </box>
          </geometry>
        </visual>
        <self_collide>0</self_collide>
        <kinematic>0</kinematic>
        <gravity>1</gravity>
      </link>
      <joint name='wg-front-left-2-joint' type='prismatic'>
        <child>wg-front-left-2</child>
        <parent>wh-front-left</parent>
        <axis>
          <xyz>-0.809017 0 -0.587785</xyz>
          <limit>
            <lower>0</lower>
            <upper>0.008</upper>
            <effort>1</effort>
            <velocity>1</velocity>
          </limit>
          <dynamics>
            <spring_reference>0</spring_reference>
            <spring_stiffness>0</spring_stiffness>
          </dynamics>
          <use_parent_model_frame>1</use_parent_model_frame>
        </axis>
      </joint>
      <link name='wg-front-left-3'>
        <pose frame=''>0.05 -0.0375 0.011 3.14159 -0.628319 -3.14159</pose>
        <inertial>
          <pose frame=''>0 0 0 0 -0 0</pose>
          <mass>4e-05</mass>
          <inertia>
            <ixx>1.66667e-11</ixx>
            <ixy>0</ixy>
            <ixz>0</ixz>
            <iyy>5.34667e-09</iyy>
            <iyz>0</iyz>
            <izz>5.33667e-09</izz>
          </inertia>
        </inertial>
        <collision name='wg-front-left-3_collision'>
          <pose frame=''>0 0 0 0 -0 0</pose>
          <geometry>
            <box>
              <size>0.04 0.001 0.002</size>
            </box>
          </geometry>
          <max_contacts>10</max_contacts>
          <surface>
            <contact>
              <ode/>
            </contact>
            <bounce/>
            <friction>
              <torsional>
                <ode/>
              </torsional>
              <ode/>
            </friction>
          </surface>
        </collision>
        <visual name='wg-front-left-3_visual'>
          <pose frame=''>0 0 0 0 -0 0</pose>
          <geometry>
            <box>
              <size>0.04 0.001 0.002</size>
            </box>
          </geometry>
        </visual>
        <self_collide>0</self_collide>
        <kinematic>0</kinematic>
        <gravity>1</gravity>
      </link>
      <joint name='wg-front-left-3-joint' type='prismatic'>
        <child>wg-front-left-3</child>
        <parent>wh-front-left</parent>
        <axis>
          <xyz>-0.809017 0 0.587785</xyz>
          <limit>
            <lower>0</lower>
            <upper>0.008</upper>
            <effort>1</effort>
            <velocity>1</velocity>
          </limit>
          <dynamics>
            <spring_reference>0</spring_reference>
            <spring_stiffness>0</spring_stiffness>
          </dynamics>
          <use_parent_model_frame>1</use_parent_model_frame>
        </axis>
      </joint>
      <link name='wg-front-left-4'>
        <pose frame=''>0.05 -0.0375 0.011 0 -1.25664 0</pose>
        <inertial>
          <pose frame=''>0 0 0 0 -0 0</pose>
          <mass>4e-05</mass>
          <inertia>
            <ixx>1.66667e-11</ixx>
            <ixy>0</ixy>
            <ixz>0</ixz>
            <iyy>5.34667e-09</iyy>
            <iyz>0</iyz>
            <izz>5.33667e-09</izz>
          </inertia>
        </inertial>
        <collision name='wg-front-left-4_collision'>
          <pose frame=''>0 0 0 0 -0 0</pose>
          <geometry>
            <box>
              <size>0.04 0.001 0.002</size>
            </box>
          </geometry>
          <max_contacts>10</max_contacts>
          <surface>
            <contact>
              <ode/>
            </contact>
            <bounce/>
            <friction>
              <torsional>
                <ode/>
              </torsional>
              <ode/>
            </friction>
          </surface>
        </collision>
        <visual name='wg-front-left-4_visual'>
          <pose frame=''>0 0 0 0 -0 0</pose>
          <geometry>
            <box>
              <size>0.04 0.001 0.002</size>
            </box>
          </geometry>
        </visual>
        <self_collide>0</self_collide>
        <kinematic>0</kinematic>
        <gravity>1</gravity>
      </link>
      <joint name='wg-front-left-4-joint' type='prismatic'>
        <child>wg-front-left-4</child>
        <parent>wh-front-left</parent>
        <axis>
          <xyz>0.309017 0 0.951057</xyz>
          <limit>
            <lower>0</lower>
            <upper>0.008</upper>
            <effort>1</effort>
            <velocity>1</velocity>
          </limit>
          <dynamics>
            <spring_reference>0</spring_reference>
            <spring_stiffness>0</spring_stiffness>
          </dynamics>
          <use_parent_model_frame>1</use_parent_model_frame>
        </axis>
      </joint>
      <link name='wg-front-left-5'>
        <pose frame=''>0.05 -0.0375 0.011 0 -0 0</pose>
        <inertial>
          <pose frame=''>0 0 0 0 -0 0</pose>
          <mass>4e-05</mass>
          <inertia>
            <ixx>1.66667e-11</ixx>
            <ixy>0</ixy>
            <ixz>0</ixz>
            <iyy>5.34667e-09</iyy>
            <iyz>0</iyz>
            <izz>5.33667e-09</izz>
          </inertia>
        </inertial>
        <collision name='wg-front-left-5_collision'>
          <pose frame=''>0 0 0 0 -0 0</pose>
          <geometry>
            <box>
              <size>0.04 0.001 0.002</size>
            </box>
          </geometry>
          <max_contacts>10</max_contacts>
          <surface>
            <contact>
              <ode/>
            </contact>
            <bounce/>
            <friction>
              <torsional>
                <ode/>
              </torsional>
              <ode/>
            </friction>
          </surface>
        </collision>
        <visual name='wg-front-left-5_visual'>
          <pose frame=''>0 0 0 0 -0 0</pose>
          <geometry>
            <box>
              <size>0.04 0.001 0.002</size>
            </box>
          </geometry>
        </visual>
        <self_collide>0</self_collide>
        <kinematic>0</kinematic>
        <gravity>1</gravity>
      </link>
      <joint name='wg-front-left-5-joint' type='prismatic'>
        <child>wg-front-left-5</child>
        <parent>wh-front-left</parent>
        <axis>
          <xyz>1 -0 -0</xyz>
          <limit>
            <lower>0</lower>
            <upper>0.008</upper>
            <effort>1</effort>
            <velocity>1</velocity>
          </limit>
          <dynamics>
            <spring_reference>0</spring_reference>
            <spring_stiffness>0</spring_stiffness>
          </dynamics>
          <use_parent_model_frame>1</use_parent_model_frame>
        </axis>
      </joint>
      <link name='wh-front-right'>
        <pose frame=''>0.05 0.0375 0.011 0 -0 0</pose>
        <inertial>
          <pose frame=''>0 0 0 0 -0 0</pose>
          <mass>0.00314593</mass>
          <inertia>
            <ixx>3.21147e-07</ixx>
            <ixy>0</ixy>
            <ixz>0</ixz>
            <iyy>3.21147e-07</iyy>
            <iyz>0</iyz>
            <izz>6.29185e-07</izz>
          </inertia>
        </inertial>
        <collision name='wh-front-right_collision'>
          <pose frame=''>0 0 0 1.57075 -0 0</pose>
          <geometry>
            <cylinder>
              <length>0.005</length>
              <radius>0.02</radius>
            </cylinder>
          </geometry>
          <max_contacts>10</max_contacts>
          <surface>
            <contact>
              <ode/>
            </contact>
            <bounce/>
            <friction>
              <torsional>
                <ode/>
              </torsional>
              <ode/>
            </friction>
          </surface>
        </collision>
        <visual name='wh-front-right_visual'>
          <pose frame=''>0 0 0 1.57075 -0 0</pose>
          <geometry>
            <cylinder>
              <length>0.005</length>
              <radius>0.02</radius>
            </cylinder>
          </geometry>
        </visual>
        <self_collide>0</self_collide>
        <kinematic>0</kinematic>
        <gravity>1</gravity>
      </link>
      <joint name='ax-front-right' type='revolute'>
        <child>wh-front-right</child>
        <parent>base_link</parent>
        <axis>
          <xyz>0 1 0</xyz>
          <limit>
            <lower>-1e+16</lower>
            <upper>1e+16</upper>
          </limit>
          <dynamics>
            <spring_reference>0</spring_reference>
            <spring_stiffness>0</spring_stiffness>
          </dynamics>
          <use_parent_model_frame>1</use_parent_model_frame>
        </axis>
      </joint>
      <link name='wg-front-right-1'>
        <pose frame=''>0.05 0.0375 0.011 0 1.25664 0</pose>
        <inertial>
          <pose frame=''>0 0 0 0 -0 0</pose>
          <mass>4e-05</mass>
          <inertia>
            <ixx>1.66667e-11</ixx>
            <ixy>0</ixy>
            <ixz>0</ixz>
            <iyy>5.34667e-09</iyy>
            <iyz>0</iyz>
            <izz>5.33667e-09</izz>
          </inertia>
        </inertial>
        <collision name='wg-front-right-1_collision'>
          <pose frame=''>0 0 0 0 -0 0</pose>
          <geometry>
            <box>
              <size>0.04 0.001 0.002</size>
            </box>
          </geometry>
          <max_contacts>10</max_contacts>
          <surface>
            <contact>
              <ode/>
            </contact>
            <bounce/>
            <friction>
              <torsional>
                <ode/>
              </torsional>
              <ode/>
            </friction>
          </surface>
        </collision>
        <visual name='wg-front-right-1_visual'>
          <pose frame=''>0 0 0 0 -0 0</pose>
          <geometry>
            <box>
              <size>0.04 0.001 0.002</size>
            </box>
          </geometry>
        </visual>
        <self_collide>0</self_collide>
        <kinematic>0</kinematic>
        <gravity>1</gravity>
      </link>
      <joint name='wg-front-right-1-joint' type='prismatic'>
        <child>wg-front-right-1</child>
        <parent>wh-front-right</parent>
        <axis>
          <xyz>0.309017 0 -0.951057</xyz>
          <limit>
            <lower>0</lower>
            <upper>0.008</upper>
            <effort>1</effort>
            <velocity>1</velocity>
          </limit>
          <dynamics>
            <spring_reference>0</spring_reference>
            <spring_stiffness>0</spring_stiffness>
          </dynamics>
          <use_parent_model_frame>1</use_parent_model_frame>
        </axis>
      </joint>
      <link name='wg-front-right-2'>
        <pose frame=''>0.05 0.0375 0.011 3.14159 0.628319 3.14159</pose>
        <inertial>
          <pose frame=''>0 0 0 0 -0 0</pose>
          <mass>4e-05</mass>
          <inertia>
            <ixx>1.66667e-11</ixx>
            <ixy>0</ixy>
            <ixz>0</ixz>
            <iyy>5.34667e-09</iyy>
            <iyz>0</iyz>
            <izz>5.33667e-09</izz>
          </inertia>
        </inertial>
        <collision name='wg-front-right-2_collision'>
          <pose frame=''>0 0 0 0 -0 0</pose>
          <geometry>
            <box>
              <size>0.04 0.001 0.002</size>
            </box>
          </geometry>
          <max_contacts>10</max_contacts>
          <surface>
            <contact>
              <ode/>
            </contact>
            <bounce/>
            <friction>
              <torsional>
                <ode/>
              </torsional>
              <ode/>
            </friction>
          </surface>
        </collision>
        <visual name='wg-front-right-2_visual'>
          <pose frame=''>0 0 0 0 -0 0</pose>
          <geometry>
            <box>
              <size>0.04 0.001 0.002</size>
            </box>
          </geometry>
        </visual>
        <self_collide>0</self_collide>
        <kinematic>0</kinematic>
        <gravity>1</gravity>
      </link>
      <joint name='wg-front-right-2-joint' type='prismatic'>
        <child>wg-front-right-2</child>
        <parent>wh-front-right</parent>
        <axis>
          <xyz>-0.809017 0 -0.587785</xyz>
          <limit>
            <lower>0</lower>
            <upper>0.008</upper>
            <effort>1</effort>
            <velocity>1</velocity>
          </limit>
          <dynamics>
            <spring_reference>0</spring_reference>
            <spring_stiffness>0</spring_stiffness>
          </dynamics>
          <use_parent_model_frame>1</use_parent_model_frame>
        </axis>
      </joint>
      <link name='wg-front-right-3'>
        <pose frame=''>0.05 0.0375 0.011 3.14159 -0.628319 -3.14159</pose>
        <inertial>
          <pose frame=''>0 0 0 0 -0 0</pose>
          <mass>4e-05</mass>
          <inertia>
            <ixx>1.66667e-11</ixx>
            <ixy>0</ixy>
            <ixz>0</ixz>
            <iyy>5.34667e-09</iyy>
            <iyz>0</iyz>
            <izz>5.33667e-09</izz>
          </inertia>
        </inertial>
        <collision name='wg-front-right-3_collision'>
          <pose frame=''>0 0 0 0 -0 0</pose>
          <geometry>
            <box>
              <size>0.04 0.001 0.002</size>
            </box>
          </geometry>
          <max_contacts>10</max_contacts>
          <surface>
            <contact>
              <ode/>
            </contact>
            <bounce/>
            <friction>
              <torsional>
                <ode/>
              </torsional>
              <ode/>
            </friction>
          </surface>
        </collision>
        <visual name='wg-front-right-3_visual'>
          <pose frame=''>0 0 0 0 -0 0</pose>
          <geometry>
            <box>
              <size>0.04 0.001 0.002</size>
            </box>
          </geometry>
        </visual>
        <self_collide>0</self_collide>
        <kinematic>0</kinematic>
        <gravity>1</gravity>
      </link>
      <joint name='wg-front-right-3-joint' type='prismatic'>
        <child>wg-front-right-3</child>
        <parent>wh-front-right</parent>
        <axis>
          <xyz>-0.809017 0 0.587785</xyz>
          <limit>
            <lower>0</lower>
            <upper>0.008</upper>
            <effort>1</effort>
            <velocity>1</velocity>
          </limit>
          <dynamics>
            <spring_reference>0</spring_reference>
            <spring_stiffness>0</spring_stiffness>
          </dynamics>
          <use_parent_model_frame>1</use_parent_model_frame>
        </axis>
      </joint>
      <link name='wg-front-right-4'>
        <pose frame=''>0.05 0.0375 0.011 0 -1.25664 0</pose>
        <inertial>
          <pose frame=''>0 0 0 0 -0 0</pose>
          <mass>4e-05</mass>
          <inertia>
            <ixx>1.66667e-11</ixx>
            <ixy>0</ixy>
            <ixz>0</ixz>
            <iyy>5.34667e-09</iyy>
            <iyz>0</iyz>
            <izz>5.33667e-09</izz>
          </inertia>
        </inertial>
        <collision name='wg-front-right-4_collision'>
          <pose frame=''>0 0 0 0 -0 0</pose>
          <geometry>
            <box>
              <size>0.04 0.001 0.002</size>
            </box>
          </geometry>
          <max_contacts>10</max_contacts>
          <surface>
            <contact>
              <ode/>
            </contact>
            <bounce/>
            <friction>
              <torsional>
                <ode/>
              </torsional>
              <ode/>
            </friction>
          </surface>
        </collision>
        <visual name='wg-front-right-4_visual'>
          <pose frame=''>0 0 0 0 -0 0</pose>
          <geometry>
            <box>
              <size>0.04 0.001 0.002</size>
            </box>
          </geometry>
        </visual>
        <self_collide>0</self_collide>
        <kinematic>0</kinematic>
        <gravity>1</gravity>
      </link>
      <joint name='wg-front-right-4-joint' type='prismatic'>
        <child>wg-front-right-4</child>
        <parent>wh-front-right</parent>
        <axis>
          <xyz>0.309017 0 0.951057</xyz>
          <limit>
            <lower>0</lower>
            <upper>0.008</upper>
            <effort>1</effort>
            <velocity>1</velocity>
          </limit>
          <dynamics>
            <spring_reference>0</spring_reference>
            <spring_stiffness>0</spring_stiffness>
          </dynamics>
          <use_parent_model_frame>1</use_parent_model_frame>
        </axis>
      </joint>
      <link name='wg-front-right-5'>
        <pose frame=''>0.05 0.0375 0.011 0 -0 0</pose>
        <inertial>
          <pose frame=''>0 0 0 0 -0 0</pose>
          <mass>4e-05</mass>
          <inertia>
            <ixx>1.66667e-11</ixx>
            <ixy>0</ixy>
            <ixz>0</ixz>
            <iyy>5.34667e-09</iyy>
            <iyz>0</iyz>
            <izz>5.33667e-09</izz>
          </inertia>
        </inertial>
        <collision name='wg-front-right-5_collision'>
          <pose frame=''>0 0 0 0 -0 0</pose>
          <geometry>
            <box>
              <size>0.04 0.001 0.002</size>
            </box>
          </geometry>
          <max_contacts>10</max_contacts>
          <surface>
            <contact>
              <ode/>
            </contact>
            <bounce/>
            <friction>
              <torsional>
                <ode/>
              </torsional>
              <ode/>
            </friction>
          </surface>
        </collision>
        <visual name='wg-front-right-5_visual'>
          <pose frame=''>0 0 0 0 -0 0</pose>
          <geometry>
            <box>
              <size>0.04 0.001 0.002</size>
            </box>
          </geometry>
        </visual>
        <self_collide>0</self_collide>
        <kinematic>0</kinematic>
        <gravity>1</gravity>
      </link>
      <joint name='wg-front-right-5-joint' type='prismatic'>
        <child>wg-front-right-5</child>
        <parent>wh-front-right</parent>
        <axis>
          <xyz>1 -0 -0</xyz>
          <limit>
            <lower>0</lower>
            <upper>0.008</upper>
            <effort>1</effort>
            <velocity>1</velocity>
          </limit>
          <dynamics>
            <spring_reference>0</spring_reference>
            <spring_stiffness>0</spring_stiffness>
          </dynamics>
          <use_parent_model_frame>1</use_parent_model_frame>
        </axis>
      </joint>
      <pose frame=''>0 0 0 0 -0 0</pose>
    </model>
    <state world_name='default'>
      <sim_time>95 931000000</sim_time>
      <real_time>7 262516160</real_time>
      <wall_time>1493593180 858460860</wall_time>
      <iterations>7167</iterations>
      <model name='adabot'>
        <pose frame=''>-0.001779 -0.004989 0.009 3e-06 1e-06 0.003746</pose>
        <scale>1 1 1</scale>
        <link name='base_link'>
          <pose frame=''>-0.001779 -0.004989 0.009 3e-06 1e-06 0.003746</pose>
          <velocity>0.000103 0 0 2e-06 -9e-06 -0.000124</velocity>
          <acceleration>1.6e-05 -0.000176 0.001179 0.007788 -0.016281 -0.165768</acceleration>
          <wrench>2e-06 -2.2e-05 0.000144 0 -0 0</wrench>
        </link>
        <link name='wg-back-left-1'>
          <pose frame=''>-0.050913 -0.042673 0.018482 -0.000356 1.12619 0.003816</pose>
          <velocity>0.001546 8e-06 -0.003951 0.049685 0.066689 -0.106074</velocity>
          <acceleration>3.09232 -0.07318 -8.32663 1.70457 1.38368 -1.91121</acceleration>
          <wrench>0.000124 -3e-06 -0.000333 0 -0 0</wrench>
        </link>
        <link name='wg-back-left-2'>
          <pose frame=''>-0.057445 -0.042698 0.014497 3.14155 0.758529 -3.13787</pose>
          <velocity>6.8e-05 7e-06 3.6e-05 -0.000277 0.00602 -0.000215</velocity>
          <acceleration>-0.017497 0.007865 0.009144 -1.87208 1.4166 0.960539</acceleration>
          <wrench>-1e-06 0 0 0 -0 0</wrench>
        </link>
        <link name='wg-back-left-3'>
          <pose frame=''>-0.051638 -0.042676 0.02 3.14157 -0.498109 -3.13784</pose>
          <velocity>9.9e-05 6e-06 -1e-06 0.000181 0.006022 -0.000157</velocity>
          <acceleration>-0.006685 0.008032 -0.001082 -0.902228 1.05573 -2.83054</acceleration>
          <wrench>0 0 0 0 -0 0</wrench>
        </link>
        <link name='wg-back-left-4'>
          <pose frame=''>-0.051638 -0.042676 0.02 -2e-05 -1.38685 0.003767</pose>
          <velocity>9.9e-05 6e-06 -1e-06 1.9e-05 0.006021 -0.00014</velocity>
          <acceleration>-0.006685 0.008034 -0.001082 -1.72399 1.22581 -0.4298</acceleration>
          <wrench>0 0 0 0 -0 0</wrench>
        </link>
        <link name='wg-back-left-5'>
          <pose frame=''>-0.051638 -0.042676 0.02 -4e-06 -0.13021 0.003747</pose>
          <velocity>0.000104 6e-06 0 -3.3e-05 0.006021 -0.000134</velocity>
          <acceleration>-0.008129 0.008031 -0.001271 -2.20145 1.20427 2.25731</acceleration>
          <wrench>0 0 0 0 -0 0</wrench>
        </link>
        <link name='wg-back-right-1'>
          <pose frame=''>-0.051199 0.032326 0.018491 -0.000923 1.12666 0.003845</pose>
          <velocity>-0.002532 0.000115 0.007124 -0.445201 -0.10614 1.04475</velocity>
          <acceleration>-5.49123 0.096352 13.9782 -0.589135 0.754361 -1.36754</acceleration>
          <wrench>-0.00022 4e-06 0.000559 0 -0 0</wrench>
        </link>
        <link name='wg-back-right-2'>
          <pose frame=''>-0.057729 0.032302 0.0145 3.14159 0.757972 -3.13785</pose>
          <velocity>0.000132 6e-06 6.1e-05 -0.000315 0.003369 -0.000229</velocity>
          <acceleration>0.010304 0.008174 -0.023794 -2.40804 -0.141147 0.829476</acceleration>
          <wrench>0 0 -1e-06 0 -0 0</wrench>
        </link>
        <link name='wg-back-right-3'>
          <pose frame=''>-0.051919 0.032324 0.02 -3.14159 -0.498666 -3.13784</pose>
          <velocity>0.000108 6e-06 0 0.000152 0.003371 -0.000158</velocity>
          <acceleration>0.006436 0.00816 0.001859 0.406621 -0.508973 -0.140965</acceleration>
          <wrench>0 0 0 0 -0 0</wrench>
        </link>
        <link name='wg-back-right-4'>
          <pose frame=''>-0.051919 0.032324 0.02 5e-05 -1.38629 0.003697</pose>
          <velocity>0.000108 6e-06 0 1.1e-05 0.00337 -0.000145</velocity>
          <acceleration>0.006438 0.008162 0.001858 -2.07977 -0.357657 -2.15454</acceleration>
          <wrench>0 0 0 0 -0 0</wrench>
        </link>
        <link name='wg-back-right-5'>
          <pose frame=''>-0.051919 0.032324 0.02 1e-05 -0.129653 0.003745</pose>
          <velocity>0.000115 6e-06 1e-06 -3.4e-05 0.00337 -0.000139</velocity>
          <acceleration>0.004662 0.008157 0.001627 -1.48153 -0.359131 1.53177</acceleration>
          <wrench>0 0 0 0 -0 0</wrench>
        </link>
        <link name='wg-front-left-1'>
          <pose frame=''>0.049089 -0.042299 0.01848 0.000992 1.12524 0.003677</pose>
          <velocity>-0.002554 -0.000135 0.007152 0.428964 -0.105422 -0.999618</velocity>
          <acceleration>-5.53583 -0.151627 14.0207 -1.84983 -0.388949 0.1449</acceleration>
          <wrench>-0.000221 -6e-06 0.000561 0 -0 0</wrench>
        </link>
        <link name='wg-front-left-2'>
          <pose frame=''>0.042558 -0.042323 0.014493 -3.14149 0.759262 -3.13788</pose>
          <velocity>0.000289 -2.3e-05 -0.000111 0.025743 -0.030341 0.0267</velocity>
          <acceleration>-0.037854 0.038985 -0.359233 -3.11184 -0.5533 0.579285</acceleration>
          <wrench>-2e-06 2e-06 -1.4e-05 0 -0 0</wrench>
        </link>
        <link name='wg-front-left-3'>
          <pose frame=''>0.048362 -0.042301 0.02 3.14156 -0.497247 -3.13784</pose>
          <velocity>-1.2e-05 -7e-06 6.1e-05 0.000136 0.001847 -0.000137</velocity>
          <acceleration>0.02166 -0.008891 -0.012768 1.86085 1.38318 2.55508</acceleration>
          <wrench>1e-06 0 -1e-06 0 -0 0</wrench>
        </link>
        <link name='wg-front-left-4'>
          <pose frame=''>0.048361 -0.042301 0.02 -6e-06 -1.38771 0.003753</pose>
          <velocity>9.9e-05 -7e-06 1e-06 -2e-05 0.001847 -0.000111</velocity>
          <acceleration>-0.006014 -0.008997 0.002247 0.823591 1.50685 0.523115</acceleration>
          <wrench>0 0 0 0 -0 0</wrench>
        </link>
        <link name='wg-front-left-5'>
          <pose frame=''>0.048361 -0.042301 0.02 -2e-06 -0.131072 0.003746</pose>
          <velocity>9.9e-05 -7e-06 1e-06 -7.4e-05 0.001846 -0.000113</velocity>
          <acceleration>-0.006014 -0.008998 0.002247 -2.36722 1.51916 1.43561</acceleration>
          <wrench>0 0 0 0 -0 0</wrench>
        </link>
        <link name='wg-front-right-1'>
          <pose frame=''>0.048815 0.032701 0.018468 0.000622 1.12474 0.003792</pose>
          <velocity>0.003285 1.8e-05 -0.007499 -0.040211 0.067486 0.10936</velocity>
          <acceleration>3.878 0.013513 -7.94517 0.271414 0.847552 1.37709</acceleration>
          <wrench>0.000155 1e-06 -0.000318 0 -0 0</wrench>
        </link>
        <link name='wg-front-right-2'>
          <pose frame=''>0.042286 0.032677 0.014499 -3.14065 0.759514 -3.13797</pose>
          <velocity>0.00251 0.000226 0.003311 -0.958545 0.1311 -0.984359</velocity>
          <acceleration>5.27779 0.324249 6.69552 2.82736 -1.41162 -1.90017</acceleration>
          <wrench>0.000211 1.3e-05 0.000268 0 -0 0</wrench>
        </link>
        <link name='wg-front-right-3'>
          <pose frame=''>0.048083 0.032698 0.019999 3.14149 -0.496631 -3.13781</pose>
          <velocity>-0.000413 -8e-06 0.000286 0.00025 0.010715 -0.00024</velocity>
          <acceleration>0.149391 -0.007481 -0.072141 2.09876 1.18044 2.6997</acceleration>
          <wrench>6e-06 0 -3e-06 0 -0 0</wrench>
        </link>
        <link name='wg-front-right-4'>
          <pose frame=''>0.04808 0.032698 0.02 -3.8e-05 -1.38833 0.003787</pose>
          <velocity>0.000117 -6e-06 -1e-06 6.2e-05 0.010714 -0.000229</velocity>
          <acceleration>0.016988 -0.00798 -0.000371 1.26428 0.914514 -1.36993</acceleration>
          <wrench>1e-06 0 0 0 -0 0</wrench>
        </link>
        <link name='wg-front-right-5'>
          <pose frame=''>0.04808 0.032698 0.02 -1e-05 -0.131688 0.003746</pose>
          <velocity>0.000117 -6e-06 -1e-06 2e-05 0.010714 -0.000214</velocity>
          <acceleration>0.01699 -0.007981 -0.000371 2.81916 0.967954 -0.747244</acceleration>
          <wrench>1e-06 0 0 0 -0 0</wrench>
        </link>
        <link name='wh-back-left'>
          <pose frame=''>-0.051638 -0.042675 0.02 9.3e-05 -0.130206 0.00374</pose>
          <velocity>0.000103 4e-06 1e-06 -0.000505 0.00515 -8e-05</velocity>
          <acceleration>0.003078 0.00671 0.003086 -0.329549 0.190404 -0.051101</acceleration>
          <wrench>1e-05 2.1e-05 1e-05 0 -0 0</wrench>
        </link>
        <link name='wh-back-right'>
          <pose frame=''>-0.051919 0.032323 0.02 -8e-05 -0.129648 0.003751</pose>
          <velocity>0.0001 6e-06 -2e-06 -1.5e-05 0.004924 6e-06</velocity>
          <acceleration>-0.006619 0.006729 -0.002715 -0.328652 -0.387556 -0.010607</acceleration>
          <wrench>-2.1e-05 2.1e-05 -9e-06 0 -0 0</wrench>
        </link>
        <link name='wh-front-left'>
          <pose frame=''>0.048361 -0.042301 0.02 6.1e-05 -0.13107 0.003742</pose>
          <velocity>8.6e-05 -6e-06 -1e-06 0.000102 0.004175 -0.000323</velocity>
          <acceleration>-0.024733 -0.007545 -0.002237 0.316011 -1.36794 -0.411879</acceleration>
          <wrench>-7.8e-05 -2.4e-05 -7e-06 0 -0 0</wrench>
        </link>
        <link name='wh-front-right'>
          <pose frame=''>0.04808 0.032698 0.02 -4.5e-05 -0.131696 0.003748</pose>
          <velocity>0.000136 -4e-06 -1e-06 0.00037 0.006962 -0.000436</velocity>
          <acceleration>0.042449 -0.006533 -0.00037 -2.90221 0.826265 2.56271</acceleration>
          <wrench>0.000134 -2.1e-05 -1e-06 0 -0 0</wrench>
        </link>
      </model>
      <model name='ground_plane'>
        <pose frame=''>0 0 0 0 -0 0</pose>
        <scale>1 1 1</scale>
        <link name='link'>
          <pose frame=''>0 0 0 0 -0 0</pose>
          <velocity>0 0 0 0 -0 0</velocity>
          <acceleration>0 0 0 0 -0 0</acceleration>
          <wrench>0 0 0 0 -0 0</wrench>
        </link>
      </model>
      <model name='rockySurface'>
        <pose frame=''>1.00133 0.142201 0 0 -0 0</pose>
        <scale>1 1 1</scale>
        <link name='link_0'>
          <pose frame=''>1.00133 0.142201 0 0 -0 0</pose>
          <velocity>0 0 0 0 -0 0</velocity>
          <acceleration>0 0 0 0 -0 0</acceleration>
          <wrench>0 0 0 0 -0 0</wrench>
        </link>
      </model>
      <light name='sun'>
        <pose frame=''>0 0 10 0 -0 0</pose>
      </light>
    </state>
    <model name='rockySurface'>
      <link name='link_0'>
        <pose frame=''>0 0 0 0 -0 0</pose>
        <inertial>
          <mass>1</mass>
          <inertia>
            <ixx>0.166667</ixx>
            <ixy>0</ixy>
            <ixz>0</ixz>
            <iyy>0.166667</iyy>
            <iyz>0</iyz>
            <izz>0.166667</izz>
          </inertia>
        </inertial>
        <visual name='visual'>
          <pose frame=''>0 0 0 0 -0 0</pose>
          <geometry>
            <mesh>
              <uri>/home/dillonflohr/adabot/src/adabot_gazebo/worlds/worldModels/rockySurfaceGood.dae</uri>
              <scale>1 1 1</scale>
            </mesh>
          </geometry>
          <material>
            <lighting>1</lighting>
            <script>
              <uri>file://media/materials/scripts/gazebo.material</uri>
              <name>Gazebo/Grey</name>
            </script>
            <ambient>0.3 0.3 0.3 1</ambient>
            <diffuse>0.7 0.7 0.7 1</diffuse>
            <specular>0.01 0.01 0.01 1</specular>
            <emissive>0 0 0 1</emissive>
          </material>
          <cast_shadows>1</cast_shadows>
          <transparency>0</transparency>
        </visual>
        <collision name='collision'>
          <laser_retro>0</laser_retro>
          <max_contacts>10</max_contacts>
          <pose frame=''>0 0 0 0 -0 0</pose>
          <geometry>
            <mesh>
              <uri>/home/dillonflohr/adabot/src/adabot_gazebo/worlds/worldModels/rockySurfaceGood.dae</uri>
              <scale>1 1 1</scale>
            </mesh>
          </geometry>
          <surface>
            <friction>
              <ode>
                <mu>1</mu>
                <mu2>1</mu2>
                <fdir1>0 0 0</fdir1>
                <slip1>0</slip1>
                <slip2>0</slip2>
              </ode>
              <torsional>
                <coefficient>1</coefficient>
                <patch_radius>0</patch_radius>
                <surface_radius>0</surface_radius>
                <use_patch_radius>1</use_patch_radius>
                <ode>
                  <slip>0</slip>
                </ode>
              </torsional>
            </friction>
            <bounce>
              <restitution_coefficient>0</restitution_coefficient>
              <threshold>1e+06</threshold>
            </bounce>
            <contact>
              <collide_without_contact>0</collide_without_contact>
              <collide_without_contact_bitmask>1</collide_without_contact_bitmask>
              <collide_bitmask>1</collide_bitmask>
              <ode>
                <soft_cfm>0</soft_cfm>
                <soft_erp>0.2</soft_erp>
                <kp>1e+13</kp>
                <kd>1</kd>
                <max_vel>0.01</max_vel>
                <min_depth>0</min_depth>
              </ode>
              <bullet>
                <split_impulse>1</split_impulse>
                <split_impulse_penetration_threshold>-0.01</split_impulse_penetration_threshold>
                <soft_cfm>0</soft_cfm>
                <soft_erp>0.2</soft_erp>
                <kp>1e+13</kp>
                <kd>1</kd>
              </bullet>
            </contact>
          </surface>
        </collision>
        <self_collide>0</self_collide>
        <kinematic>0</kinematic>
      </link>
      <static>0</static>
      <allow_auto_disable>1</allow_auto_disable>
      <pose frame=''>1.00133 0.142201 0 0 -0 0</pose>
    </model>
  </world>
</sdf>
