<?xml version="1.0" ?>
<!-- =================================================================================== -->
<!-- |    This document was autogenerated by xacro from adabot.xacro                   | -->
<!-- |    EDITING THIS FILE BY HAND IS NOT RECOMMENDED                                 | -->
<!-- =================================================================================== -->
<robot name="adabot" xmlns:xacro="http://www.ros.org/wiki/xacro">
  <material name="black">
    <color rgba="0 0 0 1"/>
  </material>
  <material name="white">
    <color rgba="1 1 1 1"/>
  </material>
  <!--
         The main chassis/body
    -->
  <link name="base_link">
    <visual>
      <origin rpy="0 0 0" xyz="0 0 0.011"/>
      <geometry>
        <box size="0.1 0.07 0.035"/>
      </geometry>
      <material name="white"/>
    </visual>
    <collision>
      <origin rpy="0 0 0" xyz="0 0 0.011"/>
      <geometry>
        <box size="0.1 0.07 0.035"/>
      </geometry>
    </collision>
    <inertial>
      <mass value="0.1225"/>
      <inertia ixx="6.25260416667e-05" ixy="0" ixz="0" iyy="0.000114588541667" iyz="0" izz="0.000152104166667"/>
    </inertial>
  </link>
  <link name="wh-front-left">
    <visual>
      <origin rpy="1.57075 0 0" xyz="0 0 0"/>
      <geometry>
        <cylinder length="0.005" radius="0.02"/>
      </geometry>
      <material name="black"/>
    </visual>
    <collision>
      <origin rpy="1.57075 0 0" xyz="0 0 0"/>
      <geometry>
        <cylinder length="0.005" radius="0.02"/>
      </geometry>
    </collision>
    <inertial>
      <mass value="0.003145927"/>
      <inertia ixx="3.21146714583e-07" ixy="0" ixz="0" iyy="3.21146714583e-07" iyz="0" izz="6.291854e-07"/>
    </inertial>
  </link>
  <joint name="ax-front-left" type="continuous">
    <parent link="base_link"/>
    <child link="wh-front-left"/>
    <origin rpy="0 0 0 " xyz="0.05 -0.0375 0.011"/>
    <axis xyz="0 1 0"/>
  </joint>
  <link name="wh-front-right">
    <visual>
      <origin rpy="1.57075 0 0" xyz="0 0 0"/>
      <geometry>
        <cylinder length="0.005" radius="0.02"/>
      </geometry>
      <material name="black"/>
    </visual>
    <collision>
      <origin rpy="1.57075 0 0" xyz="0 0 0"/>
      <geometry>
        <cylinder length="0.005" radius="0.02"/>
      </geometry>
    </collision>
    <inertial>
      <mass value="0.003145927"/>
      <inertia ixx="3.21146714583e-07" ixy="0" ixz="0" iyy="3.21146714583e-07" iyz="0" izz="6.291854e-07"/>
    </inertial>
  </link>
  <joint name="ax-front-right" type="continuous">
    <parent link="base_link"/>
    <child link="wh-front-right"/>
    <origin rpy="0 0 0 " xyz="0.05 0.0375 0.011"/>
    <axis xyz="0 1 0"/>
  </joint>
  <link name="wh-back-left">
    <visual>
      <origin rpy="1.57075 0 0" xyz="0 0 0"/>
      <geometry>
        <cylinder length="0.005" radius="0.02"/>
      </geometry>
      <material name="black"/>
    </visual>
    <collision>
      <origin rpy="1.57075 0 0" xyz="0 0 0"/>
      <geometry>
        <cylinder length="0.005" radius="0.02"/>
      </geometry>
    </collision>
    <inertial>
      <mass value="0.003145927"/>
      <inertia ixx="3.21146714583e-07" ixy="0" ixz="0" iyy="3.21146714583e-07" iyz="0" izz="6.291854e-07"/>
    </inertial>
  </link>
  <joint name="ax-back-left" type="continuous">
    <parent link="base_link"/>
    <child link="wh-back-left"/>
    <origin rpy="0 0 0 " xyz="-0.05 -0.0375 0.011"/>
    <axis xyz="0 1 0"/>
  </joint>
  <link name="wh-back-right">
    <visual>
      <origin rpy="1.57075 0 0" xyz="0 0 0"/>
      <geometry>
        <cylinder length="0.005" radius="0.02"/>
      </geometry>
      <material name="black"/>
    </visual>
    <collision>
      <origin rpy="1.57075 0 0" xyz="0 0 0"/>
      <geometry>
        <cylinder length="0.005" radius="0.02"/>
      </geometry>
    </collision>
    <inertial>
      <mass value="0.003145927"/>
      <inertia ixx="3.21146714583e-07" ixy="0" ixz="0" iyy="3.21146714583e-07" iyz="0" izz="6.291854e-07"/>
    </inertial>
  </link>
  <joint name="ax-back-right" type="continuous">
    <parent link="base_link"/>
    <child link="wh-back-right"/>
    <origin rpy="0 0 0 " xyz="-0.05 0.0375 0.011"/>
    <axis xyz="0 1 0"/>
  </joint>
</robot>

