<?xml version="1.0" ?>
<!-- =================================================================================== -->
<!-- |    This document was autogenerated by xacro from adabot.xacro                   | -->
<!-- |    EDITING THIS FILE BY HAND IS NOT RECOMMENDED                                 | -->
<!-- =================================================================================== -->
<robot name="adabot" xmlns:xacro="http://www.ros.org/wiki/xacro">
  <material name="black">
    <color rgba="0 0 0 1"/>
  </material>
  <material name="white">
    <color rgba="1 1 1 1"/>
  </material>
  <!--
         The main chassis/body
    -->
  <link name="base_link">
    <visual>
      <geometry>
        <box size="2 2 0.5"/>
      </geometry>
      <origin rpy="0 0 0" xyz="0 0 0.275"/>
      <material name="white"/>
    </visual>
  </link>
  <link name="wh-front-left">
    <visual>
      <geometry>
        <cylinder length="0.2" radius="0.5"/>
      </geometry>
      <material name="black"/>
      <origin rpy="1.57075 0 0" xyz="0 0 0"/>
    </visual>
  </link>
  <joint name="ax-front-left" type="continuous">
    <parent link="base_link"/>
    <child link="wh-front-left"/>
    <origin rpy="0 0 0 " xyz="1.0 -1.0 0.275"/>
    <axis xyz="0 1 0"/>
  </joint>
  <link name="wh-front-right">
    <visual>
      <geometry>
        <cylinder length="0.2" radius="0.5"/>
      </geometry>
      <material name="black"/>
      <origin rpy="1.57075 0 0" xyz="0 0 0"/>
    </visual>
  </link>
  <joint name="ax-front-right" type="continuous">
    <parent link="base_link"/>
    <child link="wh-front-right"/>
    <origin rpy="0 0 0 " xyz="1.0 1.0 0.275"/>
    <axis xyz="0 1 0"/>
  </joint>
  <link name="wh-back-left">
    <visual>
      <geometry>
        <cylinder length="0.2" radius="0.5"/>
      </geometry>
      <material name="black"/>
      <origin rpy="1.57075 0 0" xyz="0 0 0"/>
    </visual>
  </link>
  <joint name="ax-back-left" type="continuous">
    <parent link="base_link"/>
    <child link="wh-back-left"/>
    <origin rpy="0 0 0 " xyz="-1.0 -1.0 0.275"/>
    <axis xyz="0 1 0"/>
  </joint>
  <link name="wh-back-right">
    <visual>
      <geometry>
        <cylinder length="0.2" radius="0.5"/>
      </geometry>
      <material name="black"/>
      <origin rpy="1.57075 0 0" xyz="0 0 0"/>
    </visual>
  </link>
  <joint name="ax-back-right" type="continuous">
    <parent link="base_link"/>
    <child link="wh-back-right"/>
    <origin rpy="0 0 0 " xyz="-1.0 1.0 0.275"/>
    <axis xyz="0 1 0"/>
  </joint>
</robot>

